Workbook

Sheet 說明
B1: 美元 AI 相關公司債監控（Bloomberg Excel Add-in）
B2: 用途：追蹤 AI 主流發行人的美元債，計算 Carry、Value、Momentum、股票動能四個因子，產出加碼／減碼研究清單。方法見 repo 的 credit-quant.md。
B3: 本活頁簿只是研究工具，訊號不構成交易建議；實際交易請依公司授權與內控流程。
B5: ■ 工作表
B6: 說明：本頁。
B7: 參數：評價日、權重、門檻、評等對照表。
B8: 發行人：24 家 AI 相關公司（超大型雲端、半導體、伺服器／網通、軟體、資料中心、AI 雲端），含股票、財報、CDS 與債券彙總。
B9: 債券：債券清單與所有計算（每列一檔，最多 400 檔）。
B10: 排行：綜合分數前 20／後 20 名，以及「分類 × 評等」的平均 OAS。
B11: 分群統計：評等曲線、發行人曲線、各因子的平均與標準差（自動計算，債券表查表引用）。
B12: 搜尋：用 BSRCH 從 SRCH 儲存的搜尋抓債券清單。
B14: ■ 使用步驟
... B49: • 每月把「債券」表另存一份歷史快照，累積後用 repo 中的 credit_quant Python 範例做回測。

Sheet 參數
A1: 參數設定
A2: 黃底藍字為可調整的參數。
A4: 評價日 | B4: =TODAY() | C4: 預設為今天；要回看特定日期可改成固定日期
A5: 1 個月前 | B5: =EDATE(B4,-1) | C5: 動能與 OAS 變化的比較日期
A6: 3 個月前 | B6: =EDATE(B4,-3)
A7: 6 個月前 | B7: =EDATE(B4,-6)
A9: Carry 分群最少檔數 | B9: 5 | C9: 「評等 × 天期」分群不足此檔數時，改用評等分群
A10: 發行人曲線最少檔數 | B10: 3 | C10: 同一發行人至少幾檔才擬合發行人曲線
A11: 評等曲線最少檔數 | B11: 5 | C11: 同一評等分群至少幾檔才擬合評等曲線
A13: 權重：Carry | B13: 1 | C13: 綜合分數 = 各 z 分數依權重加權平均
A14: 權重：Value | B14: 1
A15: 權重：Momentum（債券） | B15: 0.5
A16: 權重：股票動能 | B16: 0.5 | C16: 投資等級債的動能以股票訊號為主
A18: 加碼候選門檻（百分位 ≤） | B18: 0.2 | C18: 評等分群內綜合分數前 20%
A19: 減碼候選門檻（百分位 >） | B19: 0.8 | C19: 評等分群內綜合分數後 20%
A22: 評等對照表
A23: 評等（BB_COMPOSITE） | B23: 評等分數 | C23: 評等分群
A24: AAA | B24: 1 | C24: AA以上
A25: AA+ | B25: 2 | C25: AA以上
A26: AA | B26: 3 | C26: AA以上
A27: AA- | B27: 4 | C27: AA以上
A28: A+ | B28: 5 | C28: A
A29: A | B29: 6 | C29: A
A30: A- | B30: 7 | C30: A
A31: BBB+ | B31: 8 | C31: BBB
A32: BBB | B32: 9 | C32: BBB
A33: BBB- | B33: 10 | C33: BBB
A34: BB+ | B34: 11 | C34: HY
A35: BB | B35: 12 | C35: HY
... A45: D | B45: 22 | C45: HY
A46: 評等分數：1 = AAA，數字越大評等越低。對照表以外的評等（例如 NR）不列入計算。

Sheet 發行人
A1: 發行人：AI 相關主流公司
A2: A–E 欄可自行增刪（黃底）。D 欄要和債券的 TICKER 一致才能對應；標「請確認」的請在終端機用 DES 查發債主體代碼。財報欄位以美元覆寫 (EQY_FUND_CRNCY=USD)，單位為百萬美元。
A3: 彭博欄位 → | F3: CUR_MKT_CAP | G3: CHG_PCT_6M | H3: VOLATILITY_90D | I3: SALES_REV_TURN | J3: CAPITAL_EXPEND | K3: CF_FREE_CASH_FLOW | L3: SHORT_AND_LONG_TERM_DEBT | M3: NET_DEBT | N3: EBITDA | O3: CDS_SPREAD_TICKER_5Y | P3: PX_LAST
A4: 分類 | B4: 公司 | C4: 股票代碼 | D4: 債券 Ticker | E4: 備註 | F4: 市值 (百萬 USD) | G4: 股價 6M 報酬 (%) | H4: 90 天 波動度 (%) | I4: 營收 | J4: 資本支出 | K4: 自由現金流 | L4: 總負債 | M4: 淨負債 | N4: EBITDA | O4: CDS 5Y 代碼 | P4: CDS 5Y (bp) | Q4: 淨負債 / EBITDA (x) | R4: 資本支出 / 營收 | S4: 自由現金流 / 總負債 | T4: 債券檔數 | U4: 流通在外合計 (百萬 USD) | V4: 加權平均 OAS (bp) | W4: 加權平均 DTS | X4: 平均 綜合分數 | Y4: 加碼候選 檔數 | Z4: 減碼候選 檔數
A5: 超大型雲端 | B5: Microsoft | C5: MSFT US Equity | D5: MSFT | E5: AAA 級，發債量少 | F5: =IF($C5="","",BDP($C5,F$3)) | G5: =IF($C5="","",BDP($C5,G$3)) | H5: =IF($C5="","",BDP($C5,H$3)) | I5: =IF($C5="","",BDP($C5,I$3,"EQY_FUND_CRNCY","USD")) | J5: =IF($C5="","",BDP($C5,J$3,"EQY_FUND_CRNCY","USD")) | K5: =IF($C5="","",BDP($C5,K$3,"EQY_FUND_CRNCY","USD")) | L5: =IF($C5="","",BDP($C5,L$3,"EQY_FUND_CRNCY","USD")) | M5: =IF($C5="","",BDP($C5,M$3,"EQY_FUND_CRNCY","USD")) | N5: =IF($C5="","",BDP($C5,N$3,"EQY_FUND_CRNCY","USD")) | O5: =IF($C5="","",BDP($C5,O$3)) | P5: =IF(LEFT($O5,1)="#","",IF($O5="","",BDP($O5,P$3))) | Q5: =IF(AND(ISNUMBER($M5),ISNUMBER($N5)),IF($N5>0,$M5/$N5,""),"") | R5: =IF(AND(ISNUMBER($J5),ISNUMBER($I5)),IF($I5>0,ABS($J5)/$I5,""),"") | S5: =IF(AND(ISNUMBER($K5),ISNUMBER($L5)),IF($L5>0,$K5/$L5,""),"") | T5: =IF($D5="","",COUNTIFS('債券'!$B$5:$B$404,$D5,'債券'!$Y$5:$Y$404,1)) | U5: =IF($D5="","",SUMPRODUCT(('債券'!$B$5:$B$404=$D5)*('債券'!$Y$5:$Y$404=1)*'債券'!$AV$5:$AV$404)/1E6) | V5: =IF($D5="","",IF(SUMPRODUCT(('債券'!$B$5:$B$404=$D5)*('債券'!$Y$5:$Y$404=1)*'債券'!$AV$5:$AV$404)>0,SUMPRODUCT(('債券'!$B$5:$B$404=$D5)*('債券'!$Y$5:$Y$404=1)*'債券'!$AV$5:$AV$404*'債券'!$AT$5:$AT$404)/SUMPRODUCT(('債券'!$B$5:$B$404=$D5)*('債券'!$Y$5:$Y$404=1)*'債券'!$AV$5:$AV$404),"")) | W5: =IF($D5="","",IF(SUMPRODUCT(('債券'!$B$5:$B$404=$D5)*('債券'!$Y$5:$Y$404=1)*'債券'!$AV$5:$AV$404)>0,SUMPRODUCT(('債券'!$B$5:$B$404=$D5)*('債券'!$Y$5:$Y$404=1)*'債券'!$AV$5:$AV$404*'債券'!$AW$5:$AW$404)/SUMPRODUCT(('債券'!$B$5:$B$404=$D5)*('債券'!$Y$5:$Y$404=1)*'債券'!$AV$5:$AV$404),"")) | X5: =IF($D5="","",IFERROR(AVERAGEIFS('債券'!$AQ$5:$AQ$404,'債券'!$B$5:$B$404,$D5,'債券'!$Y$5:$Y$404,1),"")) | Y5: =IF($D5="","",COUNTIFS('債券'!$B$5:$B$404,$D5,'債券'!$AS$5:$AS$404,"加碼候選")) | Z5: =IF($D5="","",COUNTIFS('債券'!$B$5:$B$404,$D5,'債券'!$AS$5:$AS$404,"減碼候選"))
A6: 超大型雲端 | B6: Alphabet | C6: GOOGL US Equity | D6: GOOGL | E6: AI 資本支出擴大後恢復發債 | F6: =IF($C6="","",BDP($C6,F$3)) | G6: =IF($C6="","",BDP($C6,G$3)) | H6: =IF($C6="","",BDP($C6,H$3)) | I6: =IF($C6="","",BDP($C6,I$3,"EQY_FUND_CRNCY","USD")) | J6: =IF($C6="","",BDP($C6,J$3,"EQY_FUND_CRNCY","USD")) | K6: =IF($C6="","",BDP($C6,K$3,"EQY_FUND_CRNCY","USD")) | L6: =IF($C6="","",BDP($C6,L$3,"EQY_FUND_CRNCY","USD")) | M6: =IF($C6="","",BDP($C6,M$3,"EQY_FUND_CRNCY","USD")) | N6: =IF($C6="","",BDP($C6,N$3,"EQY_FUND_CRNCY","USD")) | O6: =IF($C6="","",BDP($C6,O$3)) | P6: =IF(LEFT($O6,1)="#","",IF($O6="","",BDP($O6,P$3))) | Q6: =IF(AND(ISNUMBER($M6),ISNUMBER($N6)),IF($N6>0,$M6/$N6,""),"") | R6: =IF(AND(ISNUMBER($J6),ISNUMBER($I6)),IF($I6>0,ABS($J6)/$I6,""),"") | S6: =IF(AND(ISNUMBER($K6),ISNUMBER($L6)),IF($L6>0,$K6/$L6,""),"") | T6: =IF($D6="","",COUNTIFS('債券'!$B$5:$B$404,$D6,'債券'!$Y$5:$Y$404,1)) | U6: =IF($D6="","",SUMPRODUCT(('債券'!$B$5:$B$404=$D6)*('債券'!$Y$5:$Y$404=1)*'債券'!$AV$5:$AV$404)/1E6) | V6: =IF($D6="","",IF(SUMPRODUCT(('債券'!$B$5:$B$404=$D6)*('債券'!$Y$5:$Y$404=1)*'債券'!$AV$5:$AV$404)>0,SUMPRODUCT(('債券'!$B$5:$B$404=$D6)*('債券'!$Y$5:$Y$404=1)*'債券'!$AV$5:$AV$404*'債券'!$AT$5:$AT$404)/SUMPRODUCT(('債券'!$B$5:$B$404=$D6)*('債券'!$Y$5:$Y$404=1)*'債券'!$AV$5:$AV$404),"")) | W6: =IF($D6="","",IF(SUMPRODUCT(('債券'!$B$5:$B$404=$D6)*('債券'!$Y$5:$Y$404=1)*'債券'!$AV$5:$AV$404)>0,SUMPRODUCT(('債券'!$B$5:$B$404=$D6)*('債券'!$Y$5:$Y$404=1)*'債券'!$AV$5:$AV$404*'債券'!$AW$5:$AW$404)/SUMPRODUCT(('債券'!$B$5:$B$404=$D6)*('債券'!$Y$5:$Y$404=1)*'債券'!$AV$5:$AV$404),"")) | X6: =IF($D6="","",IFERROR(AVERAGEIFS('債券'!$AQ$5:$AQ$404,'債券'!$B$5:$B$404,$D6,'債券'!$Y$5:$Y$404,1),"")) | Y6: =IF($D6="","",COUNTIFS('債券'!$B$5:$B$404,$D6,'債券'!$AS$5:$AS$404,"加碼候選")) | Z6: =IF($D6="","",COUNTIFS('債券'!$B$5:$B$404,$D6,'債券'!$AS$5:$AS$404,"減碼候選"))
A7: 超大型雲端 | B7: Amazon | C7: AMZN US Equity | D7: AMZN | F7: =IF($C7="","",BDP($C7,F$3)) | G7: =IF($C7="","",BDP($C7,G$3)) | H7: =IF($C7="","",BDP($C7,H$3)) | I7: =IF($C7="","",BDP($C7,I$3,"EQY_FUND_CRNCY","USD")) | J7: =IF($C7="","",BDP($C7,J$3,"EQY_FUND_CRNCY","USD")) | K7: =IF($C7="","",BDP($C7,K$3,"EQY_FUND_CRNCY","USD")) | L7: =IF($C7="","",BDP($C7,L$3,"EQY_FUND_CRNCY","USD")) | M7: =IF($C7="","",BDP($C7,M$3,"EQY_FUND_CRNCY","USD")) | N7: =IF($C7="","",BDP($C7,N$3,"EQY_FUND_CRNCY","USD")) | O7: =IF($C7="","",BDP($C7,O$3)) | P7: =IF(LEFT($O7,1)="#","",IF($O7="","",BDP($O7,P$3))) | Q7: =IF(AND(ISNUMBER($M7),ISNUMBER($N7)),IF($N7>0,$M7/$N7,""),"") | R7: =IF(AND(ISNUMBER($J7),ISNUMBER($I7)),IF($I7>0,ABS($J7)/$I7,""),"") | S7: =IF(AND(ISNUMBER($K7),ISNUMBER($L7)),IF($L7>0,$K7/$L7,""),"") | T7: =IF($D7="","",COUNTIFS('債券'!$B$5:$B$404,$D7,'債券'!$Y$5:$Y$404,1)) | U7: =IF($D7="","",SUMPRODUCT(('債券'!$B$5:$B$404=$D7)*('債券'!$Y$5:$Y$404=1)*'債券'!$AV$5:$AV$404)/1E6) | V7: =IF($D7="","",IF(SUMPRODUCT(('債券'!$B$5:$B$404=$D7)*('債券'!$Y$5:$Y$404=1)*'債券'!$AV$5:$AV$404)>0,SUMPRODUCT(('債券'!$B$5:$B$404=$D7)*('債券'!$Y$5:$Y$404=1)*'債券'!$AV$5:$AV$404*'債券'!$AT$5:$AT$404)/SUMPRODUCT(('債券'!$B$5:$B$404=$D7)*('債券'!$Y$5:$Y$404=1)*'債券'!$AV$5:$AV$404),"")) | W7: =IF($D7="","",IF(SUMPRODUCT(('債券'!$B$5:$B$404=$D7)*('債券'!$Y$5:$Y$404=1)*'債券'!$AV$5:$AV$404)>0,SUMPRODUCT(('債券'!$B$5:$B$404=$D7)*('債券'!$Y$5:$Y$404=1)*'債券'!$AV$5:$AV$404*'債券'!$AW$5:$AW$404)/SUMPRODUCT(('債券'!$B$5:$B$404=$D7)*('債券'!$Y$5:$Y$404=1)*'債券'!$AV$5:$AV$404),"")) | X7: =IF($D7="","",IFERROR(AVERAGEIFS('債券'!$AQ$5:$AQ$404,'債券'!$B$5:$B$404,$D7,'債券'!$Y$5:$Y$404,1),"")) | Y7: =IF($D7="","",COUNTIFS('債券'!$B$5:$B$404,$D7,'債券'!$AS$5:$AS$404,"加碼候選")) | Z7: =IF($D7="","",COUNTIFS('債券'!$B$5:$B$404,$D7,'債券'!$AS$5:$AS$404,"減碼候選"))
A8: 超大型雲端 | B8: Meta Platforms | C8: META US Equity | D8: META | E8: 大量發債支應資料中心；另有表外 SPV 融資 | F8: =IF($C8="","",BDP($C8,F$3)) | G8: =IF($C8="","",BDP($C8,G$3)) | H8: =IF($C8="","",BDP($C8,H$3)) | I8: =IF($C8="","",BDP($C8,I$3,"EQY_FUND_CRNCY","USD")) | J8: =IF($C8="","",BDP($C8,J$3,"EQY_FUND_CRNCY","USD")) | K8: =IF($C8="","",BDP($C8,K$3,"EQY_FUND_CRNCY","USD")) | L8: =IF($C8="","",BDP($C8,L$3,"EQY_FUND_CRNCY","USD")) | M8: =IF($C8="","",BDP($C8,M$3,"EQY_FUND_CRNCY","USD")) | N8: =IF($C8="","",BDP($C8,N$3,"EQY_FUND_CRNCY","USD")) | O8: =IF($C8="","",BDP($C8,O$3)) | P8: =IF(LEFT($O8,1)="#","",IF($O8="","",BDP($O8,P$3))) | Q8: =IF(AND(ISNUMBER($M8),ISNUMBER($N8)),IF($N8>0,$M8/$N8,""),"") | R8: =IF(AND(ISNUMBER($J8),ISNUMBER($I8)),IF($I8>0,ABS($J8)/$I8,""),"") | S8: =IF(AND(ISNUMBER($K8),ISNUMBER($L8)),IF($L8>0,$K8/$L8,""),"") | T8: =IF($D8="","",COUNTIFS('債券'!$B$5:$B$404,$D8,'債券'!$Y$5:$Y$404,1)) | U8: =IF($D8="","",SUMPRODUCT(('債券'!$B$5:$B$404=$D8)*('債券'!$Y$5:$Y$404=1)*'債券'!$AV$5:$AV$404)/1E6) | V8: =IF($D8="","",IF(SUMPRODUCT(('債券'!$B$5:$B$404=$D8)*('債券'!$Y$5:$Y$404=1)*'債券'!$AV$5:$AV$404)>0,SUMPRODUCT(('債券'!$B$5:$B$404=$D8)*('債券'!$Y$5:$Y$404=1)*'債券'!$AV$5:$AV$404*'債券'!$AT$5:$AT$404)/SUMPRODUCT(('債券'!$B$5:$B$404=$D8)*('債券'!$Y$5:$Y$404=1)*'債券'!$AV$5:$AV$404),"")) | W8: =IF($D8="","",IF(SUMPRODUCT(('債券'!$B$5:$B$404=$D8)*('債券'!$Y$5:$Y$404=1)*'債券'!$AV$5:$AV$404)>0,SUMPRODUCT(('債券'!$B$5:$B$404=$D8)*('債券'!$Y$5:$Y$404=1)*'債券'!$AV$5:$AV$404*'債券'!$AW$5:$AW$404)/SUMPRODUCT(('債券'!$B$5:$B$404=$D8)*('債券'!$Y$5:$Y$404=1)*'債券'!$AV$5:$AV$404),"")) | X8: =IF($D8="","",IFERROR(AVERAGEIFS('債券'!$AQ$5:$AQ$404,'債券'!$B$5:$B$404,$D8,'債券'!$Y$5:$Y$404,1),"")) | Y8: =IF($D8="","",COUNTIFS('債券'!$B$5:$B$404,$D8,'債券'!$AS$5:$AS$404,"加碼候選")) | Z8: =IF($D8="","",COUNTIFS('債券'!$B$5:$B$404,$D8,'債券'!$AS$5:$AS$404,"減碼候選"))
A9: 超大型雲端 | B9: Oracle | C9: ORCL US Equity | D9: ORCL | E9: 槓桿高、AI 資本支出靠舉債，留意評等與 CDS | F9: =IF($C9="","",BDP($C9,F$3)) | G9: =IF($C9="","",BDP($C9,G$3)) | H9: =IF($C9="","",BDP($C9,H$3)) | I9: =IF($C9="","",BDP($C9,I$3,"EQY_FUND_CRNCY","USD")) | J9: =IF($C9="","",BDP($C9,J$3,"EQY_FUND_CRNCY","USD")) | K9: =IF($C9="","",BDP($C9,K$3,"EQY_FUND_CRNCY","USD")) | L9: =IF($C9="","",BDP($C9,L$3,"EQY_FUND_CRNCY","USD")) | M9: =IF($C9="","",BDP($C9,M$3,"EQY_FUND_CRNCY","USD")) | N9: =IF($C9="","",BDP($C9,N$3,"EQY_FUND_CRNCY","USD")) | O9: =IF($C9="","",BDP($C9,O$3)) | P9: =IF(LEFT($O9,1)="#","",IF($O9="","",BDP($O9,P$3))) | Q9: =IF(AND(ISNUMBER($M9),ISNUMBER($N9)),IF($N9>0,$M9/$N9,""),"") | R9: =IF(AND(ISNUMBER($J9),ISNUMBER($I9)),IF($I9>0,ABS($J9)/$I9,""),"") | S9: =IF(AND(ISNUMBER($K9),ISNUMBER($L9)),IF($L9>0,$K9/$L9,""),"") | T9: =IF($D9="","",COUNTIFS('債券'!$B$5:$B$404,$D9,'債券'!$Y$5:$Y$404,1)) | U9: =IF($D9="","",SUMPRODUCT(('債券'!$B$5:$B$404=$D9)*('債券'!$Y$5:$Y$404=1)*'債券'!$AV$5:$AV$404)/1E6) | V9: =IF($D9="","",IF(SUMPRODUCT(('債券'!$B$5:$B$404=$D9)*('債券'!$Y$5:$Y$404=1)*'債券'!$AV$5:$AV$404)>0,SUMPRODUCT(('債券'!$B$5:$B$404=$D9)*('債券'!$Y$5:$Y$404=1)*'債券'!$AV$5:$AV$404*'債券'!$AT$5:$AT$404)/SUMPRODUCT(('債券'!$B$5:$B$404=$D9)*('債券'!$Y$5:$Y$404=1)*'債券'!$AV$5:$AV$404),"")) | W9: =IF($D9="","",IF(SUMPRODUCT(('債券'!$B$5:$B$404=$D9)*('債券'!$Y$5:$Y$404=1)*'債券'!$AV$5:$AV$404)>0,SUMPRODUCT(('債券'!$B$5:$B$404=$D9)*('債券'!$Y$5:$Y$404=1)*'債券'!$AV$5:$AV$404*'債券'!$AW$5:$AW$404)/SUMPRODUCT(('債券'!$B$5:$B$404=$D9)*('債券'!$Y$5:$Y$404=1)*'債券'!$AV$5:$AV$404),"")) | X9: =IF($D9="","",IFERROR(AVERAGEIFS('債券'!$AQ$5:$AQ$404,'債券'!$B$5:$B$404,$D9,'債券'!$Y$5:$Y$404,1),"")) | Y9: =IF($D9="","",COUNTIFS('債券'!$B$5:$B$404,$D9,'債券'!$AS$5:$AS$404,"加碼候選")) | Z9: =IF($D9="","",COUNTIFS('債券'!$B$5:$B$404,$D9,'債券'!$AS$5:$AS$404,"減碼候選"))
A10: 大型科技 | B10: Apple | C10: AAPL US Equity | D10: AAPL | F10: =IF($C10="","",BDP($C10,F$3)) | G10: =IF($C10="","",BDP($C10,G$3)) | H10: =IF($C10="","",BDP($C10,H$3)) | I10: =IF($C10="","",BDP($C10,I$3,"EQY_FUND_CRNCY","USD")) | J10: =IF($C10="","",BDP($C10,J$3,"EQY_FUND_CRNCY","USD")) | K10: =IF($C10="","",BDP($C10,K$3,"EQY_FUND_CRNCY","USD")) | L10: =IF($C10="","",BDP($C10,L$3,"EQY_FUND_CRNCY","USD")) | M10: =IF($C10="","",BDP($C10,M$3,"EQY_FUND_CRNCY","USD")) | N10: =IF($C10="","",BDP($C10,N$3,"EQY_FUND_CRNCY","USD")) | O10: =IF($C10="","",BDP($C10,O$3)) | P10: =IF(LEFT($O10,1)="#","",IF($O10="","",BDP($O10,P$3))) | Q10: =IF(AND(ISNUMBER($M10),ISNUMBER($N10)),IF($N10>0,$M10/$N10,""),"") | R10: =IF(AND(ISNUMBER($J10),ISNUMBER($I10)),IF($I10>0,ABS($J10)/$I10,""),"") | S10: =IF(AND(ISNUMBER($K10),ISNUMBER($L10)),IF($L10>0,$K10/$L10,""),"") | T10: =IF($D10="","",COUNTIFS('債券'!$B$5:$B$404,$D10,'債券'!$Y$5:$Y$404,1)) | U10: =IF($D10="","",SUMPRODUCT(('債券'!$B$5:$B$404=$D10)*('債券'!$Y$5:$Y$404=1)*'債券'!$AV$5:$AV$404)/1E6) | V10: =IF($D10="","",IF(SUMPRODUCT(('債券'!$B$5:$B$404=$D10)*('債券'!$Y$5:$Y$404=1)*'債券'!$AV$5:$AV$404)>0,SUMPRODUCT(('債券'!$B$5:$B$404=$D10)*('債券'!$Y$5:$Y$404=1)*'債券'!$AV$5:$AV$404*'債券'!$AT$5:$AT$404)/SUMPRODUCT(('債券'!$B$5:$B$404=$D10)*('債券'!$Y$5:$Y$404=1)*'債券'!$AV$5:$AV$404),"")) | W10: =IF($D10="","",IF(SUMPRODUCT(('債券'!$B$5:$B$404=$D10)*('債券'!$Y$5:$Y$404=1)*'債券'!$AV$5:$AV$404)>0,SUMPRODUCT(('債券'!$B$5:$B$404=$D10)*('債券'!$Y$5:$Y$404=1)*'債券'!$AV$5:$AV$404*'債券'!$AW$5:$AW$404)/SUMPRODUCT(('債券'!$B$5:$B$404=$D10)*('債券'!$Y$5:$Y$404=1)*'債券'!$AV$5:$AV$404),"")) | X10: =IF($D10="","",IFERROR(AVERAGEIFS('債券'!$AQ$5:$AQ$404,'債券'!$B$5:$B$404,$D10,'債券'!$Y$5:$Y$404,1),"")) | Y10: =IF($D10="","",COUNTIFS('債券'!$B$5:$B$404,$D10,'債券'!$AS$5:$AS$404,"加碼候選")) | Z10: =IF($D10="","",COUNTIFS('債券'!$B$5:$B$404,$D10,'債券'!$AS$5:$AS$404,"減碼候選"))
A11: 大型科技 | B11: IBM | C11: IBM US Equity | D11: IBM | F11: =IF($C11="","",BDP($C11,F$3)) | G11: =IF($C11="","",BDP($C11,G$3)) | H11: =IF($C11="","",BDP($C11,H$3)) | I11: =IF($C11="","",BDP($C11,I$3,"EQY_FUND_CRNCY","USD")) | J11: =IF($C11="","",BDP($C11,J$3,"EQY_FUND_CRNCY","USD")) | K11: =IF($C11="","",BDP($C11,K$3,"EQY_FUND_CRNCY","USD")) | L11: =IF($C11="","",BDP($C11,L$3,"EQY_FUND_CRNCY","USD")) | M11: =IF($C11="","",BDP($C11,M$3,"EQY_FUND_CRNCY","USD")) | N11: =IF($C11="","",BDP($C11,N$3,"EQY_FUND_CRNCY","USD")) | O11: =IF($C11="","",BDP($C11,O$3)) | P11: =IF(LEFT($O11,1)="#","",IF($O11="","",BDP($O11,P$3))) | Q11: =IF(AND(ISNUMBER($M11),ISNUMBER($N11)),IF($N11>0,$M11/$N11,""),"") | R11: =IF(AND(ISNUMBER($J11),ISNUMBER($I11)),IF($I11>0,ABS($J11)/$I11,""),"") | S11: =IF(AND(ISNUMBER($K11),ISNUMBER($L11)),IF($L11>0,$K11/$L11,""),"") | T11: =IF($D11="","",COUNTIFS('債券'!$B$5:$B$404,$D11,'債券'!$Y$5:$Y$404,1)) | U11: =IF($D11="","",SUMPRODUCT(('債券'!$B$5:$B$404=$D11)*('債券'!$Y$5:$Y$404=1)*'債券'!$AV$5:$AV$404)/1E6) | V11: =IF($D11="","",IF(SUMPRODUCT(('債券'!$B$5:$B$404=$D11)*('債券'!$Y$5:$Y$404=1)*'債券'!$AV$5:$AV$404)>0,SUMPRODUCT(('債券'!$B$5:$B$404=$D11)*('債券'!$Y$5:$Y$404=1)*'債券'!$AV$5:$AV$404*'債券'!$AT$5:$AT$404)/SUMPRODUCT(('債券'!$B$5:$B$404=$D11)*('債券'!$Y$5:$Y$404=1)*'債券'!$AV$5:$AV$404),"")) | W11: =IF($D11="","",IF(SUMPRODUCT(('債券'!$B$5:$B$404=$D11)*('債券'!$Y$5:$Y$404=1)*'債券'!$AV$5:$AV$404)>0,SUMPRODUCT(('債券'!$B$5:$B$404=$D11)*('債券'!$Y$5:$Y$404=1)*'債券'!$AV$5:$AV$404*'債券'!$AW$5:$AW$404)/SUMPRODUCT(('債券'!$B$5:$B$404=$D11)*('債券'!$Y$5:$Y$404=1)*'債券'!$AV$5:$AV$404),"")) | X11: =IF($D11="","",IFERROR(AVERAGEIFS('債券'!$AQ$5:$AQ$404,'債券'!$B$5:$B$404,$D11,'債券'!$Y$5:$Y$404,1),"")) | Y11: =IF($D11="","",COUNTIFS('債券'!$B$5:$B$404,$D11,'債券'!$AS$5:$AS$404,"加碼候選")) | Z11: =IF($D11="","",COUNTIFS('債券'!$B$5:$B$404,$D11,'債券'!$AS$5:$AS$404,"減碼候選"))
A12: 半導體 | B12: NVIDIA | C12: NVDA US Equity | D12: NVDA | E12: 淨現金，流通債券少 | F12: =IF($C12="","",BDP($C12,F$3)) | G12: =IF($C12="","",BDP($C12,G$3)) | H12: =IF($C12="","",BDP($C12,H$3)) | I12: =IF($C12="","",BDP($C12,I$3,"EQY_FUND_CRNCY","USD")) | J12: =IF($C12="","",BDP($C12,J$3,"EQY_FUND_CRNCY","USD")) | K12: =IF($C12="","",BDP($C12,K$3,"EQY_FUND_CRNCY","USD")) | L12: =IF($C12="","",BDP($C12,L$3,"EQY_FUND_CRNCY","USD")) | M12: =IF($C12="","",BDP($C12,M$3,"EQY_FUND_CRNCY","USD")) | N12: =IF($C12="","",BDP($C12,N$3,"EQY_FUND_CRNCY","USD")) | O12: =IF($C12="","",BDP($C12,O$3)) | P12: =IF(LEFT($O12,1)="#","",IF($O12="","",BDP($O12,P$3))) | Q12: =IF(AND(ISNUMBER($M12),ISNUMBER($N12)),IF($N12>0,$M12/$N12,""),"") | R12: =IF(AND(ISNUMBER($J12),ISNUMBER($I12)),IF($I12>0,ABS($J12)/$I12,""),"") | S12: =IF(AND(ISNUMBER($K12),ISNUMBER($L12)),IF($L12>0,$K12/$L12,""),"") | T12: =IF($D12="","",COUNTIFS('債券'!$B$5:$B$404,$D12,'債券'!$Y$5:$Y$404,1)) | U12: =IF($D12="","",SUMPRODUCT(('債券'!$B$5:$B$404=$D12)*('債券'!$Y$5:$Y$404=1)*'債券'!$AV$5:$AV$404)/1E6) | V12: =IF($D12="","",IF(SUMPRODUCT(('債券'!$B$5:$B$404=$D12)*('債券'!$Y$5:$Y$404=1)*'債券'!$AV$5:$AV$404)>0,SUMPRODUCT(('債券'!$B$5:$B$404=$D12)*('債券'!$Y$5:$Y$404=1)*'債券'!$AV$5:$AV$404*'債券'!$AT$5:$AT$404)/SUMPRODUCT(('債券'!$B$5:$B$404=$D12)*('債券'!$Y$5:$Y$404=1)*'債券'!$AV$5:$AV$404),"")) | W12: =IF($D12="","",IF(SUMPRODUCT(('債券'!$B$5:$B$404=$D12)*('債券'!$Y$5:$Y$404=1)*'債券'!$AV$5:$AV$404)>0,SUMPRODUCT(('債券'!$B$5:$B$404=$D12)*('債券'!$Y$5:$Y$404=1)*'債券'!$AV$5:$AV$404*'債券'!$AW$5:$AW$404)/SUMPRODUCT(('債券'!$B$5:$B$404=$D12)*('債券'!$Y$5:$Y$404=1)*'債券'!$AV$5:$AV$404),"")) | X12: =IF($D12="","",IFERROR(AVERAGEIFS('債券'!$AQ$5:$AQ$404,'債券'!$B$5:$B$404,$D12,'債券'!$Y$5:$Y$404,1),"")) | Y12: =IF($D12="","",COUNTIFS('債券'!$B$5:$B$404,$D12,'債券'!$AS$5:$AS$404,"加碼候選")) | Z12: =IF($D12="","",COUNTIFS('債券'!$B$5:$B$404,$D12,'債券'!$AS$5:$AS$404,"減碼候選"))
A13: 半導體 | B13: Broadcom | C13: AVGO US Equity | D13: AVGO | E13: 併購融資，發債量大 | F13: =IF($C13="","",BDP($C13,F$3)) | G13: =IF($C13="","",BDP($C13,G$3)) | H13: =IF($C13="","",BDP($C13,H$3)) | I13: =IF($C13="","",BDP($C13,I$3,"EQY_FUND_CRNCY","USD")) | J13: =IF($C13="","",BDP($C13,J$3,"EQY_FUND_CRNCY","USD")) | K13: =IF($C13="","",BDP($C13,K$3,"EQY_FUND_CRNCY","USD")) | L13: =IF($C13="","",BDP($C13,L$3,"EQY_FUND_CRNCY","USD")) | M13: =IF($C13="","",BDP($C13,M$3,"EQY_FUND_CRNCY","USD")) | N13: =IF($C13="","",BDP($C13,N$3,"EQY_FUND_CRNCY","USD")) | O13: =IF($C13="","",BDP($C13,O$3)) | P13: =IF(LEFT($O13,1)="#","",IF($O13="","",BDP($O13,P$3))) | Q13: =IF(AND(ISNUMBER($M13),ISNUMBER($N13)),IF($N13>0,$M13/$N13,""),"") | R13: =IF(AND(ISNUMBER($J13),ISNUMBER($I13)),IF($I13>0,ABS($J13)/$I13,""),"") | S13: =IF(AND(ISNUMBER($K13),ISNUMBER($L13)),IF($L13>0,$K13/$L13,""),"") | T13: =IF($D13="","",COUNTIFS('債券'!$B$5:$B$404,$D13,'債券'!$Y$5:$Y$404,1)) | U13: =IF($D13="","",SUMPRODUCT(('債券'!$B$5:$B$404=$D13)*('債券'!$Y$5:$Y$404=1)*'債券'!$AV$5:$AV$404)/1E6) | V13: =IF($D13="","",IF(SUMPRODUCT(('債券'!$B$5:$B$404=$D13)*('債券'!$Y$5:$Y$404=1)*'債券'!$AV$5:$AV$404)>0,SUMPRODUCT(('債券'!$B$5:$B$404=$D13)*('債券'!$Y$5:$Y$404=1)*'債券'!$AV$5:$AV$404*'債券'!$AT$5:$AT$404)/SUMPRODUCT(('債券'!$B$5:$B$404=$D13)*('債券'!$Y$5:$Y$404=1)*'債券'!$AV$5:$AV$404),"")) | W13: =IF($D13="","",IF(SUMPRODUCT(('債券'!$B$5:$B$404=$D13)*('債券'!$Y$5:$Y$404=1)*'債券'!$AV$5:$AV$404)>0,SUMPRODUCT(('債券'!$B$5:$B$404=$D13)*('債券'!$Y$5:$Y$404=1)*'債券'!$AV$5:$AV$404*'債券'!$AW$5:$AW$404)/SUMPRODUCT(('債券'!$B$5:$B$404=$D13)*('債券'!$Y$5:$Y$404=1)*'債券'!$AV$5:$AV$404),"")) | X13: =IF($D13="","",IFERROR(AVERAGEIFS('債券'!$AQ$5:$AQ$404,'債券'!$B$5:$B$404,$D13,'債券'!$Y$5:$Y$404,1),"")) | Y13: =IF($D13="","",COUNTIFS('債券'!$B$5:$B$404,$D13,'債券'!$AS$5:$AS$404,"加碼候選")) | Z13: =IF($D13="","",COUNTIFS('債券'!$B$5:$B$404,$D13,'債券'!$AS$5:$AS$404,"減碼候選"))
A14: 半導體 | B14: AMD | C14: AMD US Equity | D14: AMD | F14: =IF($C14="","",BDP($C14,F$3)) | G14: =IF($C14="","",BDP($C14,G$3)) | H14: =IF($C14="","",BDP($C14,H$3)) | I14: =IF($C14="","",BDP($C14,I$3,"EQY_FUND_CRNCY","USD")) | J14: =IF($C14="","",BDP($C14,J$3,"EQY_FUND_CRNCY","USD")) | K14: =IF($C14="","",BDP($C14,K$3,"EQY_FUND_CRNCY","USD")) | L14: =IF($C14="","",BDP($C14,L$3,"EQY_FUND_CRNCY","USD")) | M14: =IF($C14="","",BDP($C14,M$3,"EQY_FUND_CRNCY","USD")) | N14: =IF($C14="","",BDP($C14,N$3,"EQY_FUND_CRNCY","USD")) | O14: =IF($C14="","",BDP($C14,O$3)) | P14: =IF(LEFT($O14,1)="#","",IF($O14="","",BDP($O14,P$3))) | Q14: =IF(AND(ISNUMBER($M14),ISNUMBER($N14)),IF($N14>0,$M14/$N14,""),"") | R14: =IF(AND(ISNUMBER($J14),ISNUMBER($I14)),IF($I14>0,ABS($J14)/$I14,""),"") | S14: =IF(AND(ISNUMBER($K14),ISNUMBER($L14)),IF($L14>0,$K14/$L14,""),"") | T14: =IF($D14="","",COUNTIFS('債券'!$B$5:$B$404,$D14,'債券'!$Y$5:$Y$404,1)) | U14: =IF($D14="","",SUMPRODUCT(('債券'!$B$5:$B$404=$D14)*('債券'!$Y$5:$Y$404=1)*'債券'!$AV$5:$AV$404)/1E6) | V14: =IF($D14="","",IF(SUMPRODUCT(('債券'!$B$5:$B$404=$D14)*('債券'!$Y$5:$Y$404=1)*'債券'!$AV$5:$AV$404)>0,SUMPRODUCT(('債券'!$B$5:$B$404=$D14)*('債券'!$Y$5:$Y$404=1)*'債券'!$AV$5:$AV$404*'債券'!$AT$5:$AT$404)/SUMPRODUCT(('債券'!$B$5:$B$404=$D14)*('債券'!$Y$5:$Y$404=1)*'債券'!$AV$5:$AV$404),"")) | W14: =IF($D14="","",IF(SUMPRODUCT(('債券'!$B$5:$B$404=$D14)*('債券'!$Y$5:$Y$404=1)*'債券'!$AV$5:$AV$404)>0,SUMPRODUCT(('債券'!$B$5:$B$404=$D14)*('債券'!$Y$5:$Y$404=1)*'債券'!$AV$5:$AV$404*'債券'!$AW$5:$AW$404)/SUMPRODUCT(('債券'!$B$5:$B$404=$D14)*('債券'!$Y$5:$Y$404=1)*'債券'!$AV$5:$AV$404),"")) | X14: =IF($D14="","",IFERROR(AVERAGEIFS('債券'!$AQ$5:$AQ$404,'債券'!$B$5:$B$404,$D14,'債券'!$Y$5:$Y$404,1),"")) | Y14: =IF($D14="","",COUNTIFS('債券'!$B$5:$B$404,$D14,'債券'!$AS$5:$AS$404,"加碼候選")) | Z14: =IF($D14="","",COUNTIFS('債券'!$B$5:$B$404,$D14,'債券'!$AS$5:$AS$404,"減碼候選"))
A15: 半導體 | B15: Intel | C15: INTC US Equity | D15: INTC | E15: 評等下調壓力 | F15: =IF($C15="","",BDP($C15,F$3)) | G15: =IF($C15="","",BDP($C15,G$3)) | H15: =IF($C15="","",BDP($C15,H$3)) | I15: =IF($C15="","",BDP($C15,I$3,"EQY_FUND_CRNCY","USD")) | J15: =IF($C15="","",BDP($C15,J$3,"EQY_FUND_CRNCY","USD")) | K15: =IF($C15="","",BDP($C15,K$3,"EQY_FUND_CRNCY","USD")) | L15: =IF($C15="","",BDP($C15,L$3,"EQY_FUND_CRNCY","USD")) | M15: =IF($C15="","",BDP($C15,M$3,"EQY_FUND_CRNCY","USD")) | N15: =IF($C15="","",BDP($C15,N$3,"EQY_FUND_CRNCY","USD")) | O15: =IF($C15="","",BDP($C15,O$3)) | P15: =IF(LEFT($O15,1)="#","",IF($O15="","",BDP($O15,P$3))) | Q15: =IF(AND(ISNUMBER($M15),ISNUMBER($N15)),IF($N15>0,$M15/$N15,""),"") | R15: =IF(AND(ISNUMBER($J15),ISNUMBER($I15)),IF($I15>0,ABS($J15)/$I15,""),"") | S15: =IF(AND(ISNUMBER($K15),ISNUMBER($L15)),IF($L15>0,$K15/$L15,""),"") | T15: =IF($D15="","",COUNTIFS('債券'!$B$5:$B$404,$D15,'債券'!$Y$5:$Y$404,1)) | U15: =IF($D15="","",SUMPRODUCT(('債券'!$B$5:$B$404=$D15)*('債券'!$Y$5:$Y$404=1)*'債券'!$AV$5:$AV$404)/1E6) | V15: =IF($D15="","",IF(SUMPRODUCT(('債券'!$B$5:$B$404=$D15)*('債券'!$Y$5:$Y$404=1)*'債券'!$AV$5:$AV$404)>0,SUMPRODUCT(('債券'!$B$5:$B$404=$D15)*('債券'!$Y$5:$Y$404=1)*'債券'!$AV$5:$AV$404*'債券'!$AT$5:$AT$404)/SUMPRODUCT(('債券'!$B$5:$B$404=$D15)*('債券'!$Y$5:$Y$404=1)*'債券'!$AV$5:$AV$404),"")) | W15: =IF($D15="","",IF(SUMPRODUCT(('債券'!$B$5:$B$404=$D15)*('債券'!$Y$5:$Y$404=1)*'債券'!$AV$5:$AV$404)>0,SUMPRODUCT(('債券'!$B$5:$B$404=$D15)*('債券'!$Y$5:$Y$404=1)*'債券'!$AV$5:$AV$404*'債券'!$AW$5:$AW$404)/SUMPRODUCT(('債券'!$B$5:$B$404=$D15)*('債券'!$Y$5:$Y$404=1)*'債券'!$AV$5:$AV$404),"")) | X15: =IF($D15="","",IFERROR(AVERAGEIFS('債券'!$AQ$5:$AQ$404,'債券'!$B$5:$B$404,$D15,'債券'!$Y$5:$Y$404,1),"")) | Y15: =IF($D15="","",COUNTIFS('債券'!$B$5:$B$404,$D15,'債券'!$AS$5:$AS$404,"加碼候選")) | Z15: =IF($D15="","",COUNTIFS('債券'!$B$5:$B$404,$D15,'債券'!$AS$5:$AS$404,"減碼候選"))
A16: 半導體 | B16: Qualcomm | C16: QCOM US Equity | D16: QCOM | F16: =IF($C16="","",BDP($C16,F$3)) | G16: =IF($C16="","",BDP($C16,G$3)) | H16: =IF($C16="","",BDP($C16,H$3)) | I16: =IF($C16="","",BDP($C16,I$3,"EQY_FUND_CRNCY","USD")) | J16: =IF($C16="","",BDP($C16,J$3,"EQY_FUND_CRNCY","USD")) | K16: =IF($C16="","",BDP($C16,K$3,"EQY_FUND_CRNCY","USD")) | L16: =IF($C16="","",BDP($C16,L$3,"EQY_FUND_CRNCY","USD")) | M16: =IF($C16="","",BDP($C16,M$3,"EQY_FUND_CRNCY","USD")) | N16: =IF($C16="","",BDP($C16,N$3,"EQY_FUND_CRNCY","USD")) | O16: =IF($C16="","",BDP($C16,O$3)) | P16: =IF(LEFT($O16,1)="#","",IF($O16="","",BDP($O16,P$3))) | Q16: =IF(AND(ISNUMBER($M16),ISNUMBER($N16)),IF($N16>0,$M16/$N16,""),"") | R16: =IF(AND(ISNUMBER($J16),ISNUMBER($I16)),IF($I16>0,ABS($J16)/$I16,""),"") | S16: =IF(AND(ISNUMBER($K16),ISNUMBER($L16)),IF($L16>0,$K16/$L16,""),"") | T16: =IF($D16="","",COUNTIFS('債券'!$B$5:$B$404,$D16,'債券'!$Y$5:$Y$404,1)) | U16: =IF($D16="","",SUMPRODUCT(('債券'!$B$5:$B$404=$D16)*('債券'!$Y$5:$Y$404=1)*'債券'!$AV$5:$AV$404)/1E6) | V16: =IF($D16="","",IF(SUMPRODUCT(('債券'!$B$5:$B$404=$D16)*('債券'!$Y$5:$Y$404=1)*'債券'!$AV$5:$AV$404)>0,SUMPRODUCT(('債券'!$B$5:$B$404=$D16)*('債券'!$Y$5:$Y$404=1)*'債券'!$AV$5:$AV$404*'債券'!$AT$5:$AT$404)/SUMPRODUCT(('債券'!$B$5:$B$404=$D16)*('債券'!$Y$5:$Y$404=1)*'債券'!$AV$5:$AV$404),"")) | W16: =IF($D16="","",IF(SUMPRODUCT(('債券'!$B$5:$B$404=$D16)*('債券'!$Y$5:$Y$404=1)*'債券'!$AV$5:$AV$404)>0,SUMPRODUCT(('債券'!$B$5:$B$404=$D16)*('債券'!$Y$5:$Y$404=1)*'債券'!$AV$5:$AV$404*'債券'!$AW$5:$AW$404)/SUMPRODUCT(('債券'!$B$5:$B$404=$D16)*('債券'!$Y$5:$Y$404=1)*'債券'!$AV$5:$AV$404),"")) | X16: =IF($D16="","",IFERROR(AVERAGEIFS('債券'!$AQ$5:$AQ$404,'債券'!$B$5:$B$404,$D16,'債券'!$Y$5:$Y$404,1),"")) | Y16: =IF($D16="","",COUNTIFS('債券'!$B$5:$B$404,$D16,'債券'!$AS$5:$AS$404,"加碼候選")) | Z16: =IF($D16="","",COUNTIFS('債券'!$B$5:$B$404,$D16,'債券'!$AS$5:$AS$404,"減碼候選"))
A17: 半導體 | B17: Micron | C17: MU US Equity | D17: MU | E17: HBM 記憶體，景氣循環 | F17: =IF($C17="","",BDP($C17,F$3)) | G17: =IF($C17="","",BDP($C17,G$3)) | H17: =IF($C17="","",BDP($C17,H$3)) | I17: =IF($C17="","",BDP($C17,I$3,"EQY_FUND_CRNCY","USD")) | J17: =IF($C17="","",BDP($C17,J$3,"EQY_FUND_CRNCY","USD")) | K17: =IF($C17="","",BDP($C17,K$3,"EQY_FUND_CRNCY","USD")) | L17: =IF($C17="","",BDP($C17,L$3,"EQY_FUND_CRNCY","USD")) | M17: =IF($C17="","",BDP($C17,M$3,"EQY_FUND_CRNCY","USD")) | N17: =IF($C17="","",BDP($C17,N$3,"EQY_FUND_CRNCY","USD")) | O17: =IF($C17="","",BDP($C17,O$3)) | P17: =IF(LEFT($O17,1)="#","",IF($O17="","",BDP($O17,P$3))) | Q17: =IF(AND(ISNUMBER($M17),ISNUMBER($N17)),IF($N17>0,$M17/$N17,""),"") | R17: =IF(AND(ISNUMBER($J17),ISNUMBER($I17)),IF($I17>0,ABS($J17)/$I17,""),"") | S17: =IF(AND(ISNUMBER($K17),ISNUMBER($L17)),IF($L17>0,$K17/$L17,""),"") | T17: =IF($D17="","",COUNTIFS('債券'!$B$5:$B$404,$D17,'債券'!$Y$5:$Y$404,1)) | U17: =IF($D17="","",SUMPRODUCT(('債券'!$B$5:$B$404=$D17)*('債券'!$Y$5:$Y$404=1)*'債券'!$AV$5:$AV$404)/1E6) | V17: =IF($D17="","",IF(SUMPRODUCT(('債券'!$B$5:$B$404=$D17)*('債券'!$Y$5:$Y$404=1)*'債券'!$AV$5:$AV$404)>0,SUMPRODUCT(('債券'!$B$5:$B$404=$D17)*('債券'!$Y$5:$Y$404=1)*'債券'!$AV$5:$AV$404*'債券'!$AT$5:$AT$404)/SUMPRODUCT(('債券'!$B$5:$B$404=$D17)*('債券'!$Y$5:$Y$404=1)*'債券'!$AV$5:$AV$404),"")) | W17: =IF($D17="","",IF(SUMPRODUCT(('債券'!$B$5:$B$404=$D17)*('債券'!$Y$5:$Y$404=1)*'債券'!$AV$5:$AV$404)>0,SUMPRODUCT(('債券'!$B$5:$B$404=$D17)*('債券'!$Y$5:$Y$404=1)*'債券'!$AV$5:$AV$404*'債券'!$AW$5:$AW$404)/SUMPRODUCT(('債券'!$B$5:$B$404=$D17)*('債券'!$Y$5:$Y$404=1)*'債券'!$AV$5:$AV$404),"")) | X17: =IF($D17="","",IFERROR(AVERAGEIFS('債券'!$AQ$5:$AQ$404,'債券'!$B$5:$B$404,$D17,'債券'!$Y$5:$Y$404,1),"")) | Y17: =IF($D17="","",COUNTIFS('債券'!$B$5:$B$404,$D17,'債券'!$AS$5:$AS$404,"加碼候選")) | Z17: =IF($D17="","",COUNTIFS('債券'!$B$5:$B$404,$D17,'債券'!$AS$5:$AS$404,"減碼候選"))
A18: 半導體 | B18: Marvell | C18: MRVL US Equity | D18: MRVL | F18: =IF($C18="","",BDP($C18,F$3)) | G18: =IF($C18="","",BDP($C18,G$3)) | H18: =IF($C18="","",BDP($C18,H$3)) | I18: =IF($C18="","",BDP($C18,I$3,"EQY_FUND_CRNCY","USD")) | J18: =IF($C18="","",BDP($C18,J$3,"EQY_FUND_CRNCY","USD")) | K18: =IF($C18="","",BDP($C18,K$3,"EQY_FUND_CRNCY","USD")) | L18: =IF($C18="","",BDP($C18,L$3,"EQY_FUND_CRNCY","USD")) | M18: =IF($C18="","",BDP($C18,M$3,"EQY_FUND_CRNCY","USD")) | N18: =IF($C18="","",BDP($C18,N$3,"EQY_FUND_CRNCY","USD")) | O18: =IF($C18="","",BDP($C18,O$3)) | P18: =IF(LEFT($O18,1)="#","",IF($O18="","",BDP($O18,P$3))) | Q18: =IF(AND(ISNUMBER($M18),ISNUMBER($N18)),IF($N18>0,$M18/$N18,""),"") | R18: =IF(AND(ISNUMBER($J18),ISNUMBER($I18)),IF($I18>0,ABS($J18)/$I18,""),"") | S18: =IF(AND(ISNUMBER($K18),ISNUMBER($L18)),IF($L18>0,$K18/$L18,""),"") | T18: =IF($D18="","",COUNTIFS('債券'!$B$5:$B$404,$D18,'債券'!$Y$5:$Y$404,1)) | U18: =IF($D18="","",SUMPRODUCT(('債券'!$B$5:$B$404=$D18)*('債券'!$Y$5:$Y$404=1)*'債券'!$AV$5:$AV$404)/1E6) | V18: =IF($D18="","",IF(SUMPRODUCT(('債券'!$B$5:$B$404=$D18)*('債券'!$Y$5:$Y$404=1)*'債券'!$AV$5:$AV$404)>0,SUMPRODUCT(('債券'!$B$5:$B$404=$D18)*('債券'!$Y$5:$Y$404=1)*'債券'!$AV$5:$AV$404*'債券'!$AT$5:$AT$404)/SUMPRODUCT(('債券'!$B$5:$B$404=$D18)*('債券'!$Y$5:$Y$404=1)*'債券'!$AV$5:$AV$404),"")) | W18: =IF($D18="","",IF(SUMPRODUCT(('債券'!$B$5:$B$404=$D18)*('債券'!$Y$5:$Y$404=1)*'債券'!$AV$5:$AV$404)>0,SUMPRODUCT(('債券'!$B$5:$B$404=$D18)*('債券'!$Y$5:$Y$404=1)*'債券'!$AV$5:$AV$404*'債券'!$AW$5:$AW$404)/SUMPRODUCT(('債券'!$B$5:$B$404=$D18)*('債券'!$Y$5:$Y$404=1)*'債券'!$AV$5:$AV$404),"")) | X18: =IF($D18="","",IFERROR(AVERAGEIFS('債券'!$AQ$5:$AQ$404,'債券'!$B$5:$B$404,$D18,'債券'!$Y$5:$Y$404,1),"")) | Y18: =IF($D18="","",COUNTIFS('債券'!$B$5:$B$404,$D18,'債券'!$AS$5:$AS$404,"加碼候選")) | Z18: =IF($D18="","",COUNTIFS('債券'!$B$5:$B$404,$D18,'債券'!$AS$5:$AS$404,"減碼候選"))
A19: 半導體 | B19: Applied Materials | C19: AMAT US Equity | D19: AMAT | E19: 半導體設備 | F19: =IF($C19="","",BDP($C19,F$3)) | G19: =IF($C19="","",BDP($C19,G$3)) | H19: =IF($C19="","",BDP($C19,H$3)) | I19: =IF($C19="","",BDP($C19,I$3,"EQY_FUND_CRNCY","USD")) | J19: =IF($C19="","",BDP($C19,J$3,"EQY_FUND_CRNCY","USD")) | K19: =IF($C19="","",BDP($C19,K$3,"EQY_FUND_CRNCY","USD")) | L19: =IF($C19="","",BDP($C19,L$3,"EQY_FUND_CRNCY","USD")) | M19: =IF($C19="","",BDP($C19,M$3,"EQY_FUND_CRNCY","USD")) | N19: =IF($C19="","",BDP($C19,N$3,"EQY_FUND_CRNCY","USD")) | O19: =IF($C19="","",BDP($C19,O$3)) | P19: =IF(LEFT($O19,1)="#","",IF($O19="","",BDP($O19,P$3))) | Q19: =IF(AND(ISNUMBER($M19),ISNUMBER($N19)),IF($N19>0,$M19/$N19,""),"") | R19: =IF(AND(ISNUMBER($J19),ISNUMBER($I19)),IF($I19>0,ABS($J19)/$I19,""),"") | S19: =IF(AND(ISNUMBER($K19),ISNUMBER($L19)),IF($L19>0,$K19/$L19,""),"") | T19: =IF($D19="","",COUNTIFS('債券'!$B$5:$B$404,$D19,'債券'!$Y$5:$Y$404,1)) | U19: =IF($D19="","",SUMPRODUCT(('債券'!$B$5:$B$404=$D19)*('債券'!$Y$5:$Y$404=1)*'債券'!$AV$5:$AV$404)/1E6) | V19: =IF($D19="","",IF(SUMPRODUCT(('債券'!$B$5:$B$404=$D19)*('債券'!$Y$5:$Y$404=1)*'債券'!$AV$5:$AV$404)>0,SUMPRODUCT(('債券'!$B$5:$B$404=$D19)*('債券'!$Y$5:$Y$404=1)*'債券'!$AV$5:$AV$404*'債券'!$AT$5:$AT$404)/SUMPRODUCT(('債券'!$B$5:$B$404=$D19)*('債券'!$Y$5:$Y$404=1)*'債券'!$AV$5:$AV$404),"")) | W19: =IF($D19="","",IF(SUMPRODUCT(('債券'!$B$5:$B$404=$D19)*('債券'!$Y$5:$Y$404=1)*'債券'!$AV$5:$AV$404)>0,SUMPRODUCT(('債券'!$B$5:$B$404=$D19)*('債券'!$Y$5:$Y$404=1)*'債券'!$AV$5:$AV$404*'債券'!$AW$5:$AW$404)/SUMPRODUCT(('債券'!$B$5:$B$404=$D19)*('債券'!$Y$5:$Y$404=1)*'債券'!$AV$5:$AV$404),"")) | X19: =IF($D19="","",IFERROR(AVERAGEIFS('債券'!$AQ$5:$AQ$404,'債券'!$B$5:$B$404,$D19,'債券'!$Y$5:$Y$404,1),"")) | Y19: =IF($D19="","",COUNTIFS('債券'!$B$5:$B$404,$D19,'債券'!$AS$5:$AS$404,"加碼候選")) | Z19: =IF($D19="","",COUNTIFS('債券'!$B$5:$B$404,$D19,'債券'!$AS$5:$AS$404,"減碼候選"))
A20: 半導體 | B20: TSMC | C20: 2330 TT Equity | D20: 請確認 | E20: 美元債由海外子公司發行，財報為台幣（已用美元覆寫） | F20: =IF($C20="","",BDP($C20,F$3)) | G20: =IF($C20="","",BDP($C20,G$3)) | H20: =IF($C20="","",BDP($C20,H$3)) | I20: =IF($C20="","",BDP($C20,I$3,"EQY_FUND_CRNCY","USD")) | J20: =IF($C20="","",BDP($C20,J$3,"EQY_FUND_CRNCY","USD")) | K20: =IF($C20="","",BDP($C20,K$3,"EQY_FUND_CRNCY","USD")) | L20: =IF($C20="","",BDP($C20,L$3,"EQY_FUND_CRNCY","USD")) | M20: =IF($C20="","",BDP($C20,M$3,"EQY_FUND_CRNCY","USD")) | N20: =IF($C20="","",BDP($C20,N$3,"EQY_FUND_CRNCY","USD")) | O20: =IF($C20="","",BDP($C20,O$3)) | P20: =IF(LEFT($O20,1)="#","",IF($O20="","",BDP($O20,P$3))) | Q20: =IF(AND(ISNUMBER($M20),ISNUMBER($N20)),IF($N20>0,$M20/$N20,""),"") | R20: =IF(AND(ISNUMBER($J20),ISNUMBER($I20)),IF($I20>0,ABS($J20)/$I20,""),"") | S20: =IF(AND(ISNUMBER($K20),ISNUMBER($L20)),IF($L20>0,$K20/$L20,""),"") | T20: =IF($D20="","",COUNTIFS('債券'!$B$5:$B$404,$D20,'債券'!$Y$5:$Y$404,1)) | U20: =IF($D20="","",SUMPRODUCT(('債券'!$B$5:$B$404=$D20)*('債券'!$Y$5:$Y$404=1)*'債券'!$AV$5:$AV$404)/1E6) | V20: =IF($D20="","",IF(SUMPRODUCT(('債券'!$B$5:$B$404=$D20)*('債券'!$Y$5:$Y$404=1)*'債券'!$AV$5:$AV$404)>0,SUMPRODUCT(('債券'!$B$5:$B$404=$D20)*('債券'!$Y$5:$Y$404=1)*'債券'!$AV$5:$AV$404*'債券'!$AT$5:$AT$404)/SUMPRODUCT(('債券'!$B$5:$B$404=$D20)*('債券'!$Y$5:$Y$404=1)*'債券'!$AV$5:$AV$404),"")) | W20: =IF($D20="","",IF(SUMPRODUCT(('債券'!$B$5:$B$404=$D20)*('債券'!$Y$5:$Y$404=1)*'債券'!$AV$5:$AV$404)>0,SUMPRODUCT(('債券'!$B$5:$B$404=$D20)*('債券'!$Y$5:$Y$404=1)*'債券'!$AV$5:$AV$404*'債券'!$AW$5:$AW$404)/SUMPRODUCT(('債券'!$B$5:$B$404=$D20)*('債券'!$Y$5:$Y$404=1)*'債券'!$AV$5:$AV$404),"")) | X20: =IF($D20="","",IFERROR(AVERAGEIFS('債券'!$AQ$5:$AQ$404,'債券'!$B$5:$B$404,$D20,'債券'!$Y$5:$Y$404,1),"")) | Y20: =IF($D20="","",COUNTIFS('債券'!$B$5:$B$404,$D20,'債券'!$AS$5:$AS$404,"加碼候選")) | Z20: =IF($D20="","",COUNTIFS('債券'!$B$5:$B$404,$D20,'債券'!$AS$5:$AS$404,"減碼候選"))
A21: 半導體 | B21: SK hynix | C21: 000660 KS Equity | D21: 請確認 | E21: 財報為韓元（已用美元覆寫） | F21: =IF($C21="","",BDP($C21,F$3)) | G21: =IF($C21="","",BDP($C21,G$3)) | H21: =IF($C21="","",BDP($C21,H$3)) | I21: =IF($C21="","",BDP($C21,I$3,"EQY_FUND_CRNCY","USD")) | J21: =IF($C21="","",BDP($C21,J$3,"EQY_FUND_CRNCY","USD")) | K21: =IF($C21="","",BDP($C21,K$3,"EQY_FUND_CRNCY","USD")) | L21: =IF($C21="","",BDP($C21,L$3,"EQY_FUND_CRNCY","USD")) | M21: =IF($C21="","",BDP($C21,M$3,"EQY_FUND_CRNCY","USD")) | N21: =IF($C21="","",BDP($C21,N$3,"EQY_FUND_CRNCY","USD")) | O21: =IF($C21="","",BDP($C21,O$3)) | P21: =IF(LEFT($O21,1)="#","",IF($O21="","",BDP($O21,P$3))) | Q21: =IF(AND(ISNUMBER($M21),ISNUMBER($N21)),IF($N21>0,$M21/$N21,""),"") | R21: =IF(AND(ISNUMBER($J21),ISNUMBER($I21)),IF($I21>0,ABS($J21)/$I21,""),"") | S21: =IF(AND(ISNUMBER($K21),ISNUMBER($L21)),IF($L21>0,$K21/$L21,""),"") | T21: =IF($D21="","",COUNTIFS('債券'!$B$5:$B$404,$D21,'債券'!$Y$5:$Y$404,1)) | U21: =IF($D21="","",SUMPRODUCT(('債券'!$B$5:$B$404=$D21)*('債券'!$Y$5:$Y$404=1)*'債券'!$AV$5:$AV$404)/1E6) | V21: =IF($D21="","",IF(SUMPRODUCT(('債券'!$B$5:$B$404=$D21)*('債券'!$Y$5:$Y$404=1)*'債券'!$AV$5:$AV$404)>0,SUMPRODUCT(('債券'!$B$5:$B$404=$D21)*('債券'!$Y$5:$Y$404=1)*'債券'!$AV$5:$AV$404*'債券'!$AT$5:$AT$404)/SUMPRODUCT(('債券'!$B$5:$B$404=$D21)*('債券'!$Y$5:$Y$404=1)*'債券'!$AV$5:$AV$404),"")) | W21: =IF($D21="","",IF(SUMPRODUCT(('債券'!$B$5:$B$404=$D21)*('債券'!$Y$5:$Y$404=1)*'債券'!$AV$5:$AV$404)>0,SUMPRODUCT(('債券'!$B$5:$B$404=$D21)*('債券'!$Y$5:$Y$404=1)*'債券'!$AV$5:$AV$404*'債券'!$AW$5:$AW$404)/SUMPRODUCT(('債券'!$B$5:$B$404=$D21)*('債券'!$Y$5:$Y$404=1)*'債券'!$AV$5:$AV$404),"")) | X21: =IF($D21="","",IFERROR(AVERAGEIFS('債券'!$AQ$5:$AQ$404,'債券'!$B$5:$B$404,$D21,'債券'!$Y$5:$Y$404,1),"")) | Y21: =IF($D21="","",COUNTIFS('債券'!$B$5:$B$404,$D21,'債券'!$AS$5:$AS$404,"加碼候選")) | Z21: =IF($D21="","",COUNTIFS('債券'!$B$5:$B$404,$D21,'債券'!$AS$5:$AS$404,"減碼候選"))
A22: 伺服器／網通 | B22: Cisco | C22: CSCO US Equity | D22: CSCO | F22: =IF($C22="","",BDP($C22,F$3)) | G22: =IF($C22="","",BDP($C22,G$3)) | H22: =IF($C22="","",BDP($C22,H$3)) | I22: =IF($C22="","",BDP($C22,I$3,"EQY_FUND_CRNCY","USD")) | J22: =IF($C22="","",BDP($C22,J$3,"EQY_FUND_CRNCY","USD")) | K22: =IF($C22="","",BDP($C22,K$3,"EQY_FUND_CRNCY","USD")) | L22: =IF($C22="","",BDP($C22,L$3,"EQY_FUND_CRNCY","USD")) | M22: =IF($C22="","",BDP($C22,M$3,"EQY_FUND_CRNCY","USD")) | N22: =IF($C22="","",BDP($C22,N$3,"EQY_FUND_CRNCY","USD")) | O22: =IF($C22="","",BDP($C22,O$3)) | P22: =IF(LEFT($O22,1)="#","",IF($O22="","",BDP($O22,P$3))) | Q22: =IF(AND(ISNUMBER($M22),ISNUMBER($N22)),IF($N22>0,$M22/$N22,""),"") | R22: =IF(AND(ISNUMBER($J22),ISNUMBER($I22)),IF($I22>0,ABS($J22)/$I22,""),"") | S22: =IF(AND(ISNUMBER($K22),ISNUMBER($L22)),IF($L22>0,$K22/$L22,""),"") | T22: =IF($D22="","",COUNTIFS('債券'!$B$5:$B$404,$D22,'債券'!$Y$5:$Y$404,1)) | U22: =IF($D22="","",SUMPRODUCT(('債券'!$B$5:$B$404=$D22)*('債券'!$Y$5:$Y$404=1)*'債券'!$AV$5:$AV$404)/1E6) | V22: =IF($D22="","",IF(SUMPRODUCT(('債券'!$B$5:$B$404=$D22)*('債券'!$Y$5:$Y$404=1)*'債券'!$AV$5:$AV$404)>0,SUMPRODUCT(('債券'!$B$5:$B$404=$D22)*('債券'!$Y$5:$Y$404=1)*'債券'!$AV$5:$AV$404*'債券'!$AT$5:$AT$404)/SUMPRODUCT(('債券'!$B$5:$B$404=$D22)*('債券'!$Y$5:$Y$404=1)*'債券'!$AV$5:$AV$404),"")) | W22: =IF($D22="","",IF(SUMPRODUCT(('債券'!$B$5:$B$404=$D22)*('債券'!$Y$5:$Y$404=1)*'債券'!$AV$5:$AV$404)>0,SUMPRODUCT(('債券'!$B$5:$B$404=$D22)*('債券'!$Y$5:$Y$404=1)*'債券'!$AV$5:$AV$404*'債券'!$AW$5:$AW$404)/SUMPRODUCT(('債券'!$B$5:$B$404=$D22)*('債券'!$Y$5:$Y$404=1)*'債券'!$AV$5:$AV$404),"")) | X22: =IF($D22="","",IFERROR(AVERAGEIFS('債券'!$AQ$5:$AQ$404,'債券'!$B$5:$B$404,$D22,'債券'!$Y$5:$Y$404,1),"")) | Y22: =IF($D22="","",COUNTIFS('債券'!$B$5:$B$404,$D22,'債券'!$AS$5:$AS$404,"加碼候選")) | Z22: =IF($D22="","",COUNTIFS('債券'!$B$5:$B$404,$D22,'債券'!$AS$5:$AS$404,"減碼候選"))
A23: 伺服器／網通 | B23: Dell Technologies | C23: DELL US Equity | D23: DELL | E23: AI 伺服器 | F23: =IF($C23="","",BDP($C23,F$3)) | G23: =IF($C23="","",BDP($C23,G$3)) | H23: =IF($C23="","",BDP($C23,H$3)) | I23: =IF($C23="","",BDP($C23,I$3,"EQY_FUND_CRNCY","USD")) | J23: =IF($C23="","",BDP($C23,J$3,"EQY_FUND_CRNCY","USD")) | K23: =IF($C23="","",BDP($C23,K$3,"EQY_FUND_CRNCY","USD")) | L23: =IF($C23="","",BDP($C23,L$3,"EQY_FUND_CRNCY","USD")) | M23: =IF($C23="","",BDP($C23,M$3,"EQY_FUND_CRNCY","USD")) | N23: =IF($C23="","",BDP($C23,N$3,"EQY_FUND_CRNCY","USD")) | O23: =IF($C23="","",BDP($C23,O$3)) | P23: =IF(LEFT($O23,1)="#","",IF($O23="","",BDP($O23,P$3))) | Q23: =IF(AND(ISNUMBER($M23),ISNUMBER($N23)),IF($N23>0,$M23/$N23,""),"") | R23: =IF(AND(ISNUMBER($J23),ISNUMBER($I23)),IF($I23>0,ABS($J23)/$I23,""),"") | S23: =IF(AND(ISNUMBER($K23),ISNUMBER($L23)),IF($L23>0,$K23/$L23,""),"") | T23: =IF($D23="","",COUNTIFS('債券'!$B$5:$B$404,$D23,'債券'!$Y$5:$Y$404,1)) | U23: =IF($D23="","",SUMPRODUCT(('債券'!$B$5:$B$404=$D23)*('債券'!$Y$5:$Y$404=1)*'債券'!$AV$5:$AV$404)/1E6) | V23: =IF($D23="","",IF(SUMPRODUCT(('債券'!$B$5:$B$404=$D23)*('債券'!$Y$5:$Y$404=1)*'債券'!$AV$5:$AV$404)>0,SUMPRODUCT(('債券'!$B$5:$B$404=$D23)*('債券'!$Y$5:$Y$404=1)*'債券'!$AV$5:$AV$404*'債券'!$AT$5:$AT$404)/SUMPRODUCT(('債券'!$B$5:$B$404=$D23)*('債券'!$Y$5:$Y$404=1)*'債券'!$AV$5:$AV$404),"")) | W23: =IF($D23="","",IF(SUMPRODUCT(('債券'!$B$5:$B$404=$D23)*('債券'!$Y$5:$Y$404=1)*'債券'!$AV$5:$AV$404)>0,SUMPRODUCT(('債券'!$B$5:$B$404=$D23)*('債券'!$Y$5:$Y$404=1)*'債券'!$AV$5:$AV$404*'債券'!$AW$5:$AW$404)/SUMPRODUCT(('債券'!$B$5:$B$404=$D23)*('債券'!$Y$5:$Y$404=1)*'債券'!$AV$5:$AV$404),"")) | X23: =IF($D23="","",IFERROR(AVERAGEIFS('債券'!$AQ$5:$AQ$404,'債券'!$B$5:$B$404,$D23,'債券'!$Y$5:$Y$404,1),"")) | Y23: =IF($D23="","",COUNTIFS('債券'!$B$5:$B$404,$D23,'債券'!$AS$5:$AS$404,"加碼候選")) | Z23: =IF($D23="","",COUNTIFS('債券'!$B$5:$B$404,$D23,'債券'!$AS$5:$AS$404,"減碼候選"))
A24: 伺服器／網通 | B24: Hewlett Packard Enterprise | C24: HPE US Equity | D24: HPE | F24: =IF($C24="","",BDP($C24,F$3)) | G24: =IF($C24="","",BDP($C24,G$3)) | H24: =IF($C24="","",BDP($C24,H$3)) | I24: =IF($C24="","",BDP($C24,I$3,"EQY_FUND_CRNCY","USD")) | J24: =IF($C24="","",BDP($C24,J$3,"EQY_FUND_CRNCY","USD")) | K24: =IF($C24="","",BDP($C24,K$3,"EQY_FUND_CRNCY","USD")) | L24: =IF($C24="","",BDP($C24,L$3,"EQY_FUND_CRNCY","USD")) | M24: =IF($C24="","",BDP($C24,M$3,"EQY_FUND_CRNCY","USD")) | N24: =IF($C24="","",BDP($C24,N$3,"EQY_FUND_CRNCY","USD")) | O24: =IF($C24="","",BDP($C24,O$3)) | P24: =IF(LEFT($O24,1)="#","",IF($O24="","",BDP($O24,P$3))) | Q24: =IF(AND(ISNUMBER($M24),ISNUMBER($N24)),IF($N24>0,$M24/$N24,""),"") | R24: =IF(AND(ISNUMBER($J24),ISNUMBER($I24)),IF($I24>0,ABS($J24)/$I24,""),"") | S24: =IF(AND(ISNUMBER($K24),ISNUMBER($L24)),IF($L24>0,$K24/$L24,""),"") | T24: =IF($D24="","",COUNTIFS('債券'!$B$5:$B$404,$D24,'債券'!$Y$5:$Y$404,1)) | U24: =IF($D24="","",SUMPRODUCT(('債券'!$B$5:$B$404=$D24)*('債券'!$Y$5:$Y$404=1)*'債券'!$AV$5:$AV$404)/1E6) | V24: =IF($D24="","",IF(SUMPRODUCT(('債券'!$B$5:$B$404=$D24)*('債券'!$Y$5:$Y$404=1)*'債券'!$AV$5:$AV$404)>0,SUMPRODUCT(('債券'!$B$5:$B$404=$D24)*('債券'!$Y$5:$Y$404=1)*'債券'!$AV$5:$AV$404*'債券'!$AT$5:$AT$404)/SUMPRODUCT(('債券'!$B$5:$B$404=$D24)*('債券'!$Y$5:$Y$404=1)*'債券'!$AV$5:$AV$404),"")) | W24: =IF($D24="","",IF(SUMPRODUCT(('債券'!$B$5:$B$404=$D24)*('債券'!$Y$5:$Y$404=1)*'債券'!$AV$5:$AV$404)>0,SUMPRODUCT(('債券'!$B$5:$B$404=$D24)*('債券'!$Y$5:$Y$404=1)*'債券'!$AV$5:$AV$404*'債券'!$AW$5:$AW$404)/SUMPRODUCT(('債券'!$B$5:$B$404=$D24)*('債券'!$Y$5:$Y$404=1)*'債券'!$AV$5:$AV$404),"")) | X24: =IF($D24="","",IFERROR(AVERAGEIFS('債券'!$AQ$5:$AQ$404,'債券'!$B$5:$B$404,$D24,'債券'!$Y$5:$Y$404,1),"")) | Y24: =IF($D24="","",COUNTIFS('債券'!$B$5:$B$404,$D24,'債券'!$AS$5:$AS$404,"加碼候選")) | Z24: =IF($D24="","",COUNTIFS('債券'!$B$5:$B$404,$D24,'債券'!$AS$5:$AS$404,"減碼候選"))
A25: 軟體 | B25: Salesforce | C25: CRM US Equity | D25: CRM | F25: =IF($C25="","",BDP($C25,F$3)) | G25: =IF($C25="","",BDP($C25,G$3)) | H25: =IF($C25="","",BDP($C25,H$3)) | I25: =IF($C25="","",BDP($C25,I$3,"EQY_FUND_CRNCY","USD")) | J25: =IF($C25="","",BDP($C25,J$3,"EQY_FUND_CRNCY","USD")) | K25: =IF($C25="","",BDP($C25,K$3,"EQY_FUND_CRNCY","USD")) | L25: =IF($C25="","",BDP($C25,L$3,"EQY_FUND_CRNCY","USD")) | M25: =IF($C25="","",BDP($C25,M$3,"EQY_FUND_CRNCY","USD")) | N25: =IF($C25="","",BDP($C25,N$3,"EQY_FUND_CRNCY","USD")) | O25: =IF($C25="","",BDP($C25,O$3)) | P25: =IF(LEFT($O25,1)="#","",IF($O25="","",BDP($O25,P$3))) | Q25: =IF(AND(ISNUMBER($M25),ISNUMBER($N25)),IF($N25>0,$M25/$N25,""),"") | R25: =IF(AND(ISNUMBER($J25),ISNUMBER($I25)),IF($I25>0,ABS($J25)/$I25,""),"") | S25: =IF(AND(ISNUMBER($K25),ISNUMBER($L25)),IF($L25>0,$K25/$L25,""),"") | T25: =IF($D25="","",COUNTIFS('債券'!$B$5:$B$404,$D25,'債券'!$Y$5:$Y$404,1)) | U25: =IF($D25="","",SUMPRODUCT(('債券'!$B$5:$B$404=$D25)*('債券'!$Y$5:$Y$404=1)*'債券'!$AV$5:$AV$404)/1E6) | V25: =IF($D25="","",IF(SUMPRODUCT(('債券'!$B$5:$B$404=$D25)*('債券'!$Y$5:$Y$404=1)*'債券'!$AV$5:$AV$404)>0,SUMPRODUCT(('債券'!$B$5:$B$404=$D25)*('債券'!$Y$5:$Y$404=1)*'債券'!$AV$5:$AV$404*'債券'!$AT$5:$AT$404)/SUMPRODUCT(('債券'!$B$5:$B$404=$D25)*('債券'!$Y$5:$Y$404=1)*'債券'!$AV$5:$AV$404),"")) | W25: =IF($D25="","",IF(SUMPRODUCT(('債券'!$B$5:$B$404=$D25)*('債券'!$Y$5:$Y$404=1)*'債券'!$AV$5:$AV$404)>0,SUMPRODUCT(('債券'!$B$5:$B$404=$D25)*('債券'!$Y$5:$Y$404=1)*'債券'!$AV$5:$AV$404*'債券'!$AW$5:$AW$404)/SUMPRODUCT(('債券'!$B$5:$B$404=$D25)*('債券'!$Y$5:$Y$404=1)*'債券'!$AV$5:$AV$404),"")) | X25: =IF($D25="","",IFERROR(AVERAGEIFS('債券'!$AQ$5:$AQ$404,'債券'!$B$5:$B$404,$D25,'債券'!$Y$5:$Y$404,1),"")) | Y25: =IF($D25="","",COUNTIFS('債券'!$B$5:$B$404,$D25,'債券'!$AS$5:$AS$404,"加碼候選")) | Z25: =IF($D25="","",COUNTIFS('債券'!$B$5:$B$404,$D25,'債券'!$AS$5:$AS$404,"減碼候選"))
A26: 資料中心 | B26: Equinix | C26: EQIX US Equity | D26: EQIX | E26: REIT | F26: =IF($C26="","",BDP($C26,F$3)) | G26: =IF($C26="","",BDP($C26,G$3)) | H26: =IF($C26="","",BDP($C26,H$3)) | I26: =IF($C26="","",BDP($C26,I$3,"EQY_FUND_CRNCY","USD")) | J26: =IF($C26="","",BDP($C26,J$3,"EQY_FUND_CRNCY","USD")) | K26: =IF($C26="","",BDP($C26,K$3,"EQY_FUND_CRNCY","USD")) | L26: =IF($C26="","",BDP($C26,L$3,"EQY_FUND_CRNCY","USD")) | M26: =IF($C26="","",BDP($C26,M$3,"EQY_FUND_CRNCY","USD")) | N26: =IF($C26="","",BDP($C26,N$3,"EQY_FUND_CRNCY","USD")) | O26: =IF($C26="","",BDP($C26,O$3)) | P26: =IF(LEFT($O26,1)="#","",IF($O26="","",BDP($O26,P$3))) | Q26: =IF(AND(ISNUMBER($M26),ISNUMBER($N26)),IF($N26>0,$M26/$N26,""),"") | R26: =IF(AND(ISNUMBER($J26),ISNUMBER($I26)),IF($I26>0,ABS($J26)/$I26,""),"") | S26: =IF(AND(ISNUMBER($K26),ISNUMBER($L26)),IF($L26>0,$K26/$L26,""),"") | T26: =IF($D26="","",COUNTIFS('債券'!$B$5:$B$404,$D26,'債券'!$Y$5:$Y$404,1)) | U26: =IF($D26="","",SUMPRODUCT(('債券'!$B$5:$B$404=$D26)*('債券'!$Y$5:$Y$404=1)*'債券'!$AV$5:$AV$404)/1E6) | V26: =IF($D26="","",IF(SUMPRODUCT(('債券'!$B$5:$B$404=$D26)*('債券'!$Y$5:$Y$404=1)*'債券'!$AV$5:$AV$404)>0,SUMPRODUCT(('債券'!$B$5:$B$404=$D26)*('債券'!$Y$5:$Y$404=1)*'債券'!$AV$5:$AV$404*'債券'!$AT$5:$AT$404)/SUMPRODUCT(('債券'!$B$5:$B$404=$D26)*('債券'!$Y$5:$Y$404=1)*'債券'!$AV$5:$AV$404),"")) | W26: =IF($D26="","",IF(SUMPRODUCT(('債券'!$B$5:$B$404=$D26)*('債券'!$Y$5:$Y$404=1)*'債券'!$AV$5:$AV$404)>0,SUMPRODUCT(('債券'!$B$5:$B$404=$D26)*('債券'!$Y$5:$Y$404=1)*'債券'!$AV$5:$AV$404*'債券'!$AW$5:$AW$404)/SUMPRODUCT(('債券'!$B$5:$B$404=$D26)*('債券'!$Y$5:$Y$404=1)*'債券'!$AV$5:$AV$404),"")) | X26: =IF($D26="","",IFERROR(AVERAGEIFS('債券'!$AQ$5:$AQ$404,'債券'!$B$5:$B$404,$D26,'債券'!$Y$5:$Y$404,1),"")) | Y26: =IF($D26="","",COUNTIFS('債券'!$B$5:$B$404,$D26,'債券'!$AS$5:$AS$404,"加碼候選")) | Z26: =IF($D26="","",COUNTIFS('債券'!$B$5:$B$404,$D26,'債券'!$AS$5:$AS$404,"減碼候選"))
A27: 資料中心 | B27: Digital Realty | C27: DLR US Equity | D27: DLR | E27: REIT | F27: =IF($C27="","",BDP($C27,F$3)) | G27: =IF($C27="","",BDP($C27,G$3)) | H27: =IF($C27="","",BDP($C27,H$3)) | I27: =IF($C27="","",BDP($C27,I$3,"EQY_FUND_CRNCY","USD")) | J27: =IF($C27="","",BDP($C27,J$3,"EQY_FUND_CRNCY","USD")) | K27: =IF($C27="","",BDP($C27,K$3,"EQY_FUND_CRNCY","USD")) | L27: =IF($C27="","",BDP($C27,L$3,"EQY_FUND_CRNCY","USD")) | M27: =IF($C27="","",BDP($C27,M$3,"EQY_FUND_CRNCY","USD")) | N27: =IF($C27="","",BDP($C27,N$3,"EQY_FUND_CRNCY","USD")) | O27: =IF($C27="","",BDP($C27,O$3)) | P27: =IF(LEFT($O27,1)="#","",IF($O27="","",BDP($O27,P$3))) | Q27: =IF(AND(ISNUMBER($M27),ISNUMBER($N27)),IF($N27>0,$M27/$N27,""),"") | R27: =IF(AND(ISNUMBER($J27),ISNUMBER($I27)),IF($I27>0,ABS($J27)/$I27,""),"") | S27: =IF(AND(ISNUMBER($K27),ISNUMBER($L27)),IF($L27>0,$K27/$L27,""),"") | T27: =IF($D27="","",COUNTIFS('債券'!$B$5:$B$404,$D27,'債券'!$Y$5:$Y$404,1)) | U27: =IF($D27="","",SUMPRODUCT(('債券'!$B$5:$B$404=$D27)*('債券'!$Y$5:$Y$404=1)*'債券'!$AV$5:$AV$404)/1E6) | V27: =IF($D27="","",IF(SUMPRODUCT(('債券'!$B$5:$B$404=$D27)*('債券'!$Y$5:$Y$404=1)*'債券'!$AV$5:$AV$404)>0,SUMPRODUCT(('債券'!$B$5:$B$404=$D27)*('債券'!$Y$5:$Y$404=1)*'債券'!$AV$5:$AV$404*'債券'!$AT$5:$AT$404)/SUMPRODUCT(('債券'!$B$5:$B$404=$D27)*('債券'!$Y$5:$Y$404=1)*'債券'!$AV$5:$AV$404),"")) | W27: =IF($D27="","",IF(SUMPRODUCT(('債券'!$B$5:$B$404=$D27)*('債券'!$Y$5:$Y$404=1)*'債券'!$AV$5:$AV$404)>0,SUMPRODUCT(('債券'!$B$5:$B$404=$D27)*('債券'!$Y$5:$Y$404=1)*'債券'!$AV$5:$AV$404*'債券'!$AW$5:$AW$404)/SUMPRODUCT(('債券'!$B$5:$B$404=$D27)*('債券'!$Y$5:$Y$404=1)*'債券'!$AV$5:$AV$404),"")) | X27: =IF($D27="","",IFERROR(AVERAGEIFS('債券'!$AQ$5:$AQ$404,'債券'!$B$5:$B$404,$D27,'債券'!$Y$5:$Y$404,1),"")) | Y27: =IF($D27="","",COUNTIFS('債券'!$B$5:$B$404,$D27,'債券'!$AS$5:$AS$404,"加碼候選")) | Z27: =IF($D27="","",COUNTIFS('債券'!$B$5:$B$404,$D27,'債券'!$AS$5:$AS$404,"減碼候選"))
A28: AI 雲端（高收益） | B28: CoreWeave | C28: CRWV US Equity | D28: 請確認 | E28: 高收益，債務以 GPU 擔保融資為主 | F28: =IF($C28="","",BDP($C28,F$3)) | G28: =IF($C28="","",BDP($C28,G$3)) | H28: =IF($C28="","",BDP($C28,H$3)) | I28: =IF($C28="","",BDP($C28,I$3,"EQY_FUND_CRNCY","USD")) | J28: =IF($C28="","",BDP($C28,J$3,"EQY_FUND_CRNCY","USD")) | K28: =IF($C28="","",BDP($C28,K$3,"EQY_FUND_CRNCY","USD")) | L28: =IF($C28="","",BDP($C28,L$3,"EQY_FUND_CRNCY","USD")) | M28: =IF($C28="","",BDP($C28,M$3,"EQY_FUND_CRNCY","USD")) | N28: =IF($C28="","",BDP($C28,N$3,"EQY_FUND_CRNCY","USD")) | O28: =IF($C28="","",BDP($C28,O$3)) | P28: =IF(LEFT($O28,1)="#","",IF($O28="","",BDP($O28,P$3))) | Q28: =IF(AND(ISNUMBER($M28),ISNUMBER($N28)),IF($N28>0,$M28/$N28,""),"") | R28: =IF(AND(ISNUMBER($J28),ISNUMBER($I28)),IF($I28>0,ABS($J28)/$I28,""),"") | S28: =IF(AND(ISNUMBER($K28),ISNUMBER($L28)),IF($L28>0,$K28/$L28,""),"") | T28: =IF($D28="","",COUNTIFS('債券'!$B$5:$B$404,$D28,'債券'!$Y$5:$Y$404,1)) | U28: =IF($D28="","",SUMPRODUCT(('債券'!$B$5:$B$404=$D28)*('債券'!$Y$5:$Y$404=1)*'債券'!$AV$5:$AV$404)/1E6) | V28: =IF($D28="","",IF(SUMPRODUCT(('債券'!$B$5:$B$404=$D28)*('債券'!$Y$5:$Y$404=1)*'債券'!$AV$5:$AV$404)>0,SUMPRODUCT(('債券'!$B$5:$B$404=$D28)*('債券'!$Y$5:$Y$404=1)*'債券'!$AV$5:$AV$404*'債券'!$AT$5:$AT$404)/SUMPRODUCT(('債券'!$B$5:$B$404=$D28)*('債券'!$Y$5:$Y$404=1)*'債券'!$AV$5:$AV$404),"")) | W28: =IF($D28="","",IF(SUMPRODUCT(('債券'!$B$5:$B$404=$D28)*('債券'!$Y$5:$Y$404=1)*'債券'!$AV$5:$AV$404)>0,SUMPRODUCT(('債券'!$B$5:$B$404=$D28)*('債券'!$Y$5:$Y$404=1)*'債券'!$AV$5:$AV$404*'債券'!$AW$5:$AW$404)/SUMPRODUCT(('債券'!$B$5:$B$404=$D28)*('債券'!$Y$5:$Y$404=1)*'債券'!$AV$5:$AV$404),"")) | X28: =IF($D28="","",IFERROR(AVERAGEIFS('債券'!$AQ$5:$AQ$404,'債券'!$B$5:$B$404,$D28,'債券'!$Y$5:$Y$404,1),"")) | Y28: =IF($D28="","",COUNTIFS('債券'!$B$5:$B$404,$D28,'債券'!$AS$5:$AS$404,"加碼候選")) | Z28: =IF($D28="","",COUNTIFS('債券'!$B$5:$B$404,$D28,'債券'!$AS$5:$AS$404,"減碼候選"))
F29: =IF($C29="","",BDP($C29,F$3)) | G29: =IF($C29="","",BDP($C29,G$3)) | H29: =IF($C29="","",BDP($C29,H$3)) | I29: =IF($C29="","",BDP($C29,I$3,"EQY_FUND_CRNCY","USD")) | J29: =IF($C29="","",BDP($C29,J$3,"EQY_FUND_CRNCY","USD")) | K29: =IF($C29="","",BDP($C29,K$3,"EQY_FUND_CRNCY","USD")) | L29: =IF($C29="","",BDP($C29,L$3,"EQY_FUND_CRNCY","USD")) | M29: =IF($C29="","",BDP($C29,M$3,"EQY_FUND_CRNCY","USD")) | N29: =IF($C29="","",BDP($C29,N$3,"EQY_FUND_CRNCY","USD")) | O29: =IF($C29="","",BDP($C29,O$3)) | P29: =IF(LEFT($O29,1)="#","",IF($O29="","",BDP($O29,P$3))) | Q29: =IF(AND(ISNUMBER($M29),ISNUMBER($N29)),IF($N29>0,$M29/$N29,""),"") | R29: =IF(AND(ISNUMBER($J29),ISNUMBER($I29)),IF($I29>0,ABS($J29)/$I29,""),"") | S29: =IF(AND(ISNUMBER($K29),ISNUMBER($L29)),IF($L29>0,$K29/$L29,""),"") | T29: =IF($D29="","",COUNTIFS('債券'!$B$5:$B$404,$D29,'債券'!$Y$5:$Y$404,1)) | U29: =IF($D29="","",SUMPRODUCT(('債券'!$B$5:$B$404=$D29)*('債券'!$Y$5:$Y$404=1)*'債券'!$AV$5:$AV$404)/1E6) | V29: =IF($D29="","",IF(SUMPRODUCT(('債券'!$B$5:$B$404=$D29)*('債券'!$Y$5:$Y$404=1)*'債券'!$AV$5:$AV$404)>0,SUMPRODUCT(('債券'!$B$5:$B$404=$D29)*('債券'!$Y$5:$Y$404=1)*'債券'!$AV$5:$AV$404*'債券'!$AT$5:$AT$404)/SUMPRODUCT(('債券'!$B$5:$B$404=$D29)*('債券'!$Y$5:$Y$404=1)*'債券'!$AV$5:$AV$404),"")) | W29: =IF($D29="","",IF(SUMPRODUCT(('債券'!$B$5:$B$404=$D29)*('債券'!$Y$5:$Y$404=1)*'債券'!$AV$5:$AV$404)>0,SUMPRODUCT(('債券'!$B$5:$B$404=$D29)*('債券'!$Y$5:$Y$404=1)*'債券'!$AV$5:$AV$404*'債券'!$AW$5:$AW$404)/SUMPRODUCT(('債券'!$B$5:$B$404=$D29)*('債券'!$Y$5:$Y$404=1)*'債券'!$AV$5:$AV$404),"")) | X29: =IF($D29="","",IFERROR(AVERAGEIFS('債券'!$AQ$5:$AQ$404,'債券'!$B$5:$B$404,$D29,'債券'!$Y$5:$Y$404,1),"")) | Y29: =IF($D29="","",COUNTIFS('債券'!$B$5:$B$404,$D29,'債券'!$AS$5:$AS$404,"加碼候選")) | Z29: =IF($D29="","",COUNTIFS('債券'!$B$5:$B$404,$D29,'債券'!$AS$5:$AS$404,"減碼候選"))
F30: =IF($C30="","",BDP($C30,F$3)) | G30: =IF($C30="","",BDP($C30,G$3)) | H30: =IF($C30="","",BDP($C30,H$3)) | I30: =IF($C30="","",BDP($C30,I$3,"EQY_FUND_CRNCY","USD")) | J30: =IF($C30="","",BDP($C30,J$3,"EQY_FUND_CRNCY","USD")) | K30: =IF($C30="","",BDP($C30,K$3,"EQY_FUND_CRNCY","USD")) | L30: =IF($C30="","",BDP($C30,L$3,"EQY_FUND_CRNCY","USD")) | M30: =IF($C30="","",BDP($C30,M$3,"EQY_FUND_CRNCY","USD")) | N30: =IF($C30="","",BDP($C30,N$3,"EQY_FUND_CRNCY","USD")) | O30: =IF($C30="","",BDP($C30,O$3)) | P30: =IF(LEFT($O30,1)="#","",IF($O30="","",BDP($O30,P$3))) | Q30: =IF(AND(ISNUMBER($M30),ISNUMBER($N30)),IF($N30>0,$M30/$N30,""),"") | R30: =IF(AND(ISNUMBER($J30),ISNUMBER($I30)),IF($I30>0,ABS($J30)/$I30,""),"") | S30: =IF(AND(ISNUMBER($K30),ISNUMBER($L30)),IF($L30>0,$K30/$L30,""),"") | T30: =IF($D30="","",COUNTIFS('債券'!$B$5:$B$404,$D30,'債券'!$Y$5:$Y$404,1)) | U30: =IF($D30="","",SUMPRODUCT(('債券'!$B$5:$B$404=$D30)*('債券'!$Y$5:$Y$404=1)*'債券'!$AV$5:$AV$404)/1E6) | V30: =IF($D30="","",IF(SUMPRODUCT(('債券'!$B$5:$B$404=$D30)*('債券'!$Y$5:$Y$404=1)*'債券'!$AV$5:$AV$404)>0,SUMPRODUCT(('債券'!$B$5:$B$404=$D30)*('債券'!$Y$5:$Y$404=1)*'債券'!$AV$5:$AV$404*'債券'!$AT$5:$AT$404)/SUMPRODUCT(('債券'!$B$5:$B$404=$D30)*('債券'!$Y$5:$Y$404=1)*'債券'!$AV$5:$AV$404),"")) | W30: =IF($D30="","",IF(SUMPRODUCT(('債券'!$B$5:$B$404=$D30)*('債券'!$Y$5:$Y$404=1)*'債券'!$AV$5:$AV$404)>0,SUMPRODUCT(('債券'!$B$5:$B$404=$D30)*('債券'!$Y$5:$Y$404=1)*'債券'!$AV$5:$AV$404*'債券'!$AW$5:$AW$404)/SUMPRODUCT(('債券'!$B$5:$B$404=$D30)*('債券'!$Y$5:$Y$404=1)*'債券'!$AV$5:$AV$404),"")) | X30: =IF($D30="","",IFERROR(AVERAGEIFS('債券'!$AQ$5:$AQ$404,'債券'!$B$5:$B$404,$D30,'債券'!$Y$5:$Y$404,1),"")) | Y30: =IF($D30="","",COUNTIFS('債券'!$B$5:$B$404,$D30,'債券'!$AS$5:$AS$404,"加碼候選")) | Z30: =IF($D30="","",COUNTIFS('債券'!$B$5:$B$404,$D30,'債券'!$AS$5:$AS$404,"減碼候選"))
F31: =IF($C31="","",BDP($C31,F$3)) | G31: =IF($C31="","",BDP($C31,G$3)) | H31: =IF($C31="","",BDP($C31,H$3)) | I31: =IF($C31="","",BDP($C31,I$3,"EQY_FUND_CRNCY","USD")) | J31: =IF($C31="","",BDP($C31,J$3,"EQY_FUND_CRNCY","USD")) | K31: =IF($C31="","",BDP($C31,K$3,"EQY_FUND_CRNCY","USD")) | L31: =IF($C31="","",BDP($C31,L$3,"EQY_FUND_CRNCY","USD")) | M31: =IF($C31="","",BDP($C31,M$3,"EQY_FUND_CRNCY","USD")) | N31: =IF($C31="","",BDP($C31,N$3,"EQY_FUND_CRNCY","USD")) | O31: =IF($C31="","",BDP($C31,O$3)) | P31: =IF(LEFT($O31,1)="#","",IF($O31="","",BDP($O31,P$3))) | Q31: =IF(AND(ISNUMBER($M31),ISNUMBER($N31)),IF($N31>0,$M31/$N31,""),"") | R31: =IF(AND(ISNUMBER($J31),ISNUMBER($I31)),IF($I31>0,ABS($J31)/$I31,""),"") | S31: =IF(AND(ISNUMBER($K31),ISNUMBER($L31)),IF($L31>0,$K31/$L31,""),"") | T31: =IF($D31="","",COUNTIFS('債券'!$B$5:$B$404,$D31,'債券'!$Y$5:$Y$404,1)) | U31: =IF($D31="","",SUMPRODUCT(('債券'!$B$5:$B$404=$D31)*('債券'!$Y$5:$Y$404=1)*'債券'!$AV$5:$AV$404)/1E6) | V31: =IF($D31="","",IF(SUMPRODUCT(('債券'!$B$5:$B$404=$D31)*('債券'!$Y$5:$Y$404=1)*'債券'!$AV$5:$AV$404)>0,SUMPRODUCT(('債券'!$B$5:$B$404=$D31)*('債券'!$Y$5:$Y$404=1)*'債券'!$AV$5:$AV$404*'債券'!$AT$5:$AT$404)/SUMPRODUCT(('債券'!$B$5:$B$404=$D31)*('債券'!$Y$5:$Y$404=1)*'債券'!$AV$5:$AV$404),"")) | W31: =IF($D31="","",IF(SUMPRODUCT(('債券'!$B$5:$B$404=$D31)*('債券'!$Y$5:$Y$404=1)*'債券'!$AV$5:$AV$404)>0,SUMPRODUCT(('債券'!$B$5:$B$404=$D31)*('債券'!$Y$5:$Y$404=1)*'債券'!$AV$5:$AV$404*'債券'!$AW$5:$AW$404)/SUMPRODUCT(('債券'!$B$5:$B$404=$D31)*('債券'!$Y$5:$Y$404=1)*'債券'!$AV$5:$AV$404),"")) | X31: =IF($D31="","",IFERROR(AVERAGEIFS('債券'!$AQ$5:$AQ$404,'債券'!$B$5:$B$404,$D31,'債券'!$Y$5:$Y$404,1),"")) | Y31: =IF($D31="","",COUNTIFS('債券'!$B$5:$B$404,$D31,'債券'!$AS$5:$AS$404,"加碼候選")) | Z31: =IF($D31="","",COUNTIFS('債券'!$B$5:$B$404,$D31,'債券'!$AS$5:$AS$404,"減碼候選"))
F32: =IF($C32="","",BDP($C32,F$3)) | G32: =IF($C32="","",BDP($C32,G$3)) | H32: =IF($C32="","",BDP($C32,H$3)) | I32: =IF($C32="","",BDP($C32,I$3,"EQY_FUND_CRNCY","USD")) | J32: =IF($C32="","",BDP($C32,J$3,"EQY_FUND_CRNCY","USD")) | K32: =IF($C32="","",BDP($C32,K$3,"EQY_FUND_CRNCY","USD")) | L32: =IF($C32="","",BDP($C32,L$3,"EQY_FUND_CRNCY","USD")) | M32: =IF($C32="","",BDP($C32,M$3,"EQY_FUND_CRNCY","USD")) | N32: =IF($C32="","",BDP($C32,N$3,"EQY_FUND_CRNCY","USD")) | O32: =IF($C32="","",BDP($C32,O$3)) | P32: =IF(LEFT($O32,1)="#","",IF($O32="","",BDP($O32,P$3))) | Q32: =IF(AND(ISNUMBER($M32),ISNUMBER($N32)),IF($N32>0,$M32/$N32,""),"") | R32: =IF(AND(ISNUMBER($J32),ISNUMBER($I32)),IF($I32>0,ABS($J32)/$I32,""),"") | S32: =IF(AND(ISNUMBER($K32),ISNUMBER($L32)),IF($L32>0,$K32/$L32,""),"") | T32: =IF($D32="","",COUNTIFS('債券'!$B$5:$B$404,$D32,'債券'!$Y$5:$Y$404,1)) | U32: =IF($D32="","",SUMPRODUCT(('債券'!$B$5:$B$404=$D32)*('債券'!$Y$5:$Y$404=1)*'債券'!$AV$5:$AV$404)/1E6) | V32: =IF($D32="","",IF(SUMPRODUCT(('債券'!$B$5:$B$404=$D32)*('債券'!$Y$5:$Y$404=1)*'債券'!$AV$5:$AV$404)>0,SUMPRODUCT(('債券'!$B$5:$B$404=$D32)*('債券'!$Y$5:$Y$404=1)*'債券'!$AV$5:$AV$404*'債券'!$AT$5:$AT$404)/SUMPRODUCT(('債券'!$B$5:$B$404=$D32)*('債券'!$Y$5:$Y$404=1)*'債券'!$AV$5:$AV$404),"")) | W32: =IF($D32="","",IF(SUMPRODUCT(('債券'!$B$5:$B$404=$D32)*('債券'!$Y$5:$Y$404=1)*'債券'!$AV$5:$AV$404)>0,SUMPRODUCT(('債券'!$B$5:$B$404=$D32)*('債券'!$Y$5:$Y$404=1)*'債券'!$AV$5:$AV$404*'債券'!$AW$5:$AW$404)/SUMPRODUCT(('債券'!$B$5:$B$404=$D32)*('債券'!$Y$5:$Y$404=1)*'債券'!$AV$5:$AV$404),"")) | X32: =IF($D32="","",IFERROR(AVERAGEIFS('債券'!$AQ$5:$AQ$404,'債券'!$B$5:$B$404,$D32,'債券'!$Y$5:$Y$404,1),"")) | Y32: =IF($D32="","",COUNTIFS('債券'!$B$5:$B$404,$D32,'債券'!$AS$5:$AS$404,"加碼候選")) | Z32: =IF($D32="","",COUNTIFS('債券'!$B$5:$B$404,$D32,'債券'!$AS$5:$AS$404,"減碼候選"))
F33: =IF($C33="","",BDP($C33,F$3)) | G33: =IF($C33="","",BDP($C33,G$3)) | H33: =IF($C33="","",BDP($C33,H$3)) | I33: =IF($C33="","",BDP($C33,I$3,"EQY_FUND_CRNCY","USD")) | J33: =IF($C33="","",BDP($C33,J$3,"EQY_FUND_CRNCY","USD")) | K33: =IF($C33="","",BDP($C33,K$3,"EQY_FUND_CRNCY","USD")) | L33: =IF($C33="","",BDP($C33,L$3,"EQY_FUND_CRNCY","USD")) | M33: =IF($C33="","",BDP($C33,M$3,"EQY_FUND_CRNCY","USD")) | N33: =IF($C33="","",BDP($C33,N$3,"EQY_FUND_CRNCY","USD")) | O33: =IF($C33="","",BDP($C33,O$3)) | P33: =IF(LEFT($O33,1)="#","",IF($O33="","",BDP($O33,P$3))) | Q33: =IF(AND(ISNUMBER($M33),ISNUMBER($N33)),IF($N33>0,$M33/$N33,""),"") | R33: =IF(AND(ISNUMBER($J33),ISNUMBER($I33)),IF($I33>0,ABS($J33)/$I33,""),"") | S33: =IF(AND(ISNUMBER($K33),ISNUMBER($L33)),IF($L33>0,$K33/$L33,""),"") | T33: =IF($D33="","",COUNTIFS('債券'!$B$5:$B$404,$D33,'債券'!$Y$5:$Y$404,1)) | U33: =IF($D33="","",SUMPRODUCT(('債券'!$B$5:$B$404=$D33)*('債券'!$Y$5:$Y$404=1)*'債券'!$AV$5:$AV$404)/1E6) | V33: =IF($D33="","",IF(SUMPRODUCT(('債券'!$B$5:$B$404=$D33)*('債券'!$Y$5:$Y$404=1)*'債券'!$AV$5:$AV$404)>0,SUMPRODUCT(('債券'!$B$5:$B$404=$D33)*('債券'!$Y$5:$Y$404=1)*'債券'!$AV$5:$AV$404*'債券'!$AT$5:$AT$404)/SUMPRODUCT(('債券'!$B$5:$B$404=$D33)*('債券'!$Y$5:$Y$404=1)*'債券'!$AV$5:$AV$404),"")) | W33: =IF($D33="","",IF(SUMPRODUCT(('債券'!$B$5:$B$404=$D33)*('債券'!$Y$5:$Y$404=1)*'債券'!$AV$5:$AV$404)>0,SUMPRODUCT(('債券'!$B$5:$B$404=$D33)*('債券'!$Y$5:$Y$404=1)*'債券'!$AV$5:$AV$404*'債券'!$AW$5:$AW$404)/SUMPRODUCT(('債券'!$B$5:$B$404=$D33)*('債券'!$Y$5:$Y$404=1)*'債券'!$AV$5:$AV$404),"")) | X33: =IF($D33="","",IFERROR(AVERAGEIFS('債券'!$AQ$5:$AQ$404,'債券'!$B$5:$B$404,$D33,'債券'!$Y$5:$Y$404,1),"")) | Y33: =IF($D33="","",COUNTIFS('債券'!$B$5:$B$404,$D33,'債券'!$AS$5:$AS$404,"加碼候選")) | Z33: =IF($D33="","",COUNTIFS('債券'!$B$5:$B$404,$D33,'債券'!$AS$5:$AS$404,"減碼候選"))
F34: =IF($C34="","",BDP($C34,F$3)) | G34: =IF($C34="","",BDP($C34,G$3)) | H34: =IF($C34="","",BDP($C34,H$3)) | I34: =IF($C34="","",BDP($C34,I$3,"EQY_FUND_CRNCY","USD")) | J34: =IF($C34="","",BDP($C34,J$3,"EQY_FUND_CRNCY","USD")) | K34: =IF($C34="","",BDP($C34,K$3,"EQY_FUND_CRNCY","USD")) | L34: =IF($C34="","",BDP($C34,L$3,"EQY_FUND_CRNCY","USD")) | M34: =IF($C34="","",BDP($C34,M$3,"EQY_FUND_CRNCY","USD")) | N34: =IF($C34="","",BDP($C34,N$3,"EQY_FUND_CRNCY","USD")) | O34: =IF($C34="","",BDP($C34,O$3)) | P34: =IF(LEFT($O34,1)="#","",IF($O34="","",BDP($O34,P$3))) | Q34: =IF(AND(ISNUMBER($M34),ISNUMBER($N34)),IF($N34>0,$M34/$N34,""),"") | R34: =IF(AND(ISNUMBER($J34),ISNUMBER($I34)),IF($I34>0,ABS($J34)/$I34,""),"") | S34: =IF(AND(ISNUMBER($K34),ISNUMBER($L34)),IF($L34>0,$K34/$L34,""),"") | T34: =IF($D34="","",COUNTIFS('債券'!$B$5:$B$404,$D34,'債券'!$Y$5:$Y$404,1)) | U34: =IF($D34="","",SUMPRODUCT(('債券'!$B$5:$B$404=$D34)*('債券'!$Y$5:$Y$404=1)*'債券'!$AV$5:$AV$404)/1E6) | V34: =IF($D34="","",IF(SUMPRODUCT(('債券'!$B$5:$B$404=$D34)*('債券'!$Y$5:$Y$404=1)*'債券'!$AV$5:$AV$404)>0,SUMPRODUCT(('債券'!$B$5:$B$404=$D34)*('債券'!$Y$5:$Y$404=1)*'債券'!$AV$5:$AV$404*'債券'!$AT$5:$AT$404)/SUMPRODUCT(('債券'!$B$5:$B$404=$D34)*('債券'!$Y$5:$Y$404=1)*'債券'!$AV$5:$AV$404),"")) | W34: =IF($D34="","",IF(SUMPRODUCT(('債券'!$B$5:$B$404=$D34)*('債券'!$Y$5:$Y$404=1)*'債券'!$AV$5:$AV$404)>0,SUMPRODUCT(('債券'!$B$5:$B$404=$D34)*('債券'!$Y$5:$Y$404=1)*'債券'!$AV$5:$AV$404*'債券'!$AW$5:$AW$404)/SUMPRODUCT(('債券'!$B$5:$B$404=$D34)*('債券'!$Y$5:$Y$404=1)*'債券'!$AV$5:$AV$404),"")) | X34: =IF($D34="","",IFERROR(AVERAGEIFS('債券'!$AQ$5:$AQ$404,'債券'!$B$5:$B$404,$D34,'債券'!$Y$5:$Y$404,1),"")) | Y34: =IF($D34="","",COUNTIFS('債券'!$B$5:$B$404,$D34,'債券'!$AS$5:$AS$404,"加碼候選")) | Z34: =IF($D34="","",COUNTIFS('債券'!$B$5:$B$404,$D34,'債券'!$AS$5:$AS$404,"減碼候選"))
F35: =IF($C35="","",BDP($C35,F$3)) | G35: =IF($C35="","",BDP($C35,G$3)) | H35: =IF($C35="","",BDP($C35,H$3)) | I35: =IF($C35="","",BDP($C35,I$3,"EQY_FUND_CRNCY","USD")) | J35: =IF($C35="","",BDP($C35,J$3,"EQY_FUND_CRNCY","USD")) | K35: =IF($C35="","",BDP($C35,K$3,"EQY_FUND_CRNCY","USD")) | L35: =IF($C35="","",BDP($C35,L$3,"EQY_FUND_CRNCY","USD")) | M35: =IF($C35="","",BDP($C35,M$3,"EQY_FUND_CRNCY","USD")) | N35: =IF($C35="","",BDP($C35,N$3,"EQY_FUND_CRNCY","USD")) | O35: =IF($C35="","",BDP($C35,O$3)) | P35: =IF(LEFT($O35,1)="#","",IF($O35="","",BDP($O35,P$3))) | Q35: =IF(AND(ISNUMBER($M35),ISNUMBER($N35)),IF($N35>0,$M35/$N35,""),"") | R35: =IF(AND(ISNUMBER($J35),ISNUMBER($I35)),IF($I35>0,ABS($J35)/$I35,""),"") | S35: =IF(AND(ISNUMBER($K35),ISNUMBER($L35)),IF($L35>0,$K35/$L35,""),"") | T35: =IF($D35="","",COUNTIFS('債券'!$B$5:$B$404,$D35,'債券'!$Y$5:$Y$404,1)) | U35: =IF($D35="","",SUMPRODUCT(('債券'!$B$5:$B$404=$D35)*('債券'!$Y$5:$Y$404=1)*'債券'!$AV$5:$AV$404)/1E6) | V35: =IF($D35="","",IF(SUMPRODUCT(('債券'!$B$5:$B$404=$D35)*('債券'!$Y$5:$Y$404=1)*'債券'!$AV$5:$AV$404)>0,SUMPRODUCT(('債券'!$B$5:$B$404=$D35)*('債券'!$Y$5:$Y$404=1)*'債券'!$AV$5:$AV$404*'債券'!$AT$5:$AT$404)/SUMPRODUCT(('債券'!$B$5:$B$404=$D35)*('債券'!$Y$5:$Y$404=1)*'債券'!$AV$5:$AV$404),"")) | W35: =IF($D35="","",IF(SUMPRODUCT(('債券'!$B$5:$B$404=$D35)*('債券'!$Y$5:$Y$404=1)*'債券'!$AV$5:$AV$404)>0,SUMPRODUCT(('債券'!$B$5:$B$404=$D35)*('債券'!$Y$5:$Y$404=1)*'債券'!$AV$5:$AV$404*'債券'!$AW$5:$AW$404)/SUMPRODUCT(('債券'!$B$5:$B$404=$D35)*('債券'!$Y$5:$Y$404=1)*'債券'!$AV$5:$AV$404),"")) | X35: =IF($D35="","",IFERROR(AVERAGEIFS('債券'!$AQ$5:$AQ$404,'債券'!$B$5:$B$404,$D35,'債券'!$Y$5:$Y$404,1),"")) | Y35: =IF($D35="","",COUNTIFS('債券'!$B$5:$B$404,$D35,'債券'!$AS$5:$AS$404,"加碼候選")) | Z35: =IF($D35="","",COUNTIFS('債券'!$B$5:$B$404,$D35,'債券'!$AS$5:$AS$404,"減碼候選"))
